Workbook

Sheet Lead Tracker
A1: Sr no | B1: Date | C1: Company Name | D1: Location | E1: States | F1: Product Type | G1: Capacity / Specs | H1: Phone | I1: Email | J1: Inquiry Status | K1: Contact Person | L1: Lead Source | M1: Lead Owner | N1: Quotation No | O1: Quotation Date | P1: Expected Order Value | Q1: Quotation Status | R1: Order loss Analysis | S1: Remarks
A2: =ROW()-1 -> 1 | B2: 46113 | C2: SANDVIK COROMANT INDIA PVT. LTD | D2: Dapodi | E2: Maharashtra | F2: Others | G2: Winch for 1T Capacity | H2: 9767350574 | I2: KIRAN NALAGE <kiran.nalage@sandvik.com> | J2: QUOTATION REQ. | K2: Kiran Nalage | L2: REFRENCE | M2: MALLESH | N2: 05/SANDVIK-WINCH-1-04-26 | O2: 46113 | P2: 450000
A3: =ROW()-1 -> 2 | B3: 46113 | C3: KSB LIMITED | D3: admednagar | E3: Maharashtra | F3: Jib Crane | G3: of Jib Crane of 1MT Capacity | H3: 9970951430 | I3: <Jaywant.Sutar@ksb.com> | J3: QUOTATION REQ. | K3: Sutar, Jaywant' | L3: EXISTING CUS. | M3: RAVI
A4: =ROW()-1 -> 3 | B4: 46113 | F4: Hoist | G4: 2 Ton Electric Chain Hoist | H4: 9146215901 | I4: dangat9666@gmail.com | J4: NOT INTERESTED | K4: bhi | L4: INDIAMART | M4: SAKSHI
A5: =ROW()-1 -> 4 | B5: 46113 | C5: Electrofab Engineering Services Pvt.Ltd | D5: plot no. 49B,Sai industrial associates,NR Maharashtra ware house ,nashik road,chowiswadi,charoli, Pimpri Chinchwad, Maharashtra, India | E5: Maharashtra | F5: EOT Crane | G5: crane | H5: 7249020866 | I5: atharvpasalkar146@gmail.com | J5: NOT INTERESTED | K5: athrv | L5: INDIAMART | M5: VIVEK
A6: =ROW()-1 -> 5 | B6: 46113 | D6: Dharni, Maharashtra, India | G6: Portable Gantry Crane | H6: 8080534980 | I6: Dharni, Maharashtra, India | J6: CONTACTED | K6: NITESH LAXMAN SEMALKAR | L6: INDIAMART | M6: VIVEK
A7: =ROW()-1 -> 6 | B7: 46113 | C7: Sany India ltd | D7: Chakan | E7: Maharashtra | F7: Others | J7: QUOTATION REQ. | K7: Nikhil warade | L7: EXISTING CUS. | M7: RAVI
A8: =ROW()-1 -> 7 | B8: 46113 | C8: Atlas copco | D8: Chakan | E8: Maharashtra | F8: Hoist | G8: 5MT Crab Trollry | J8: QUOTATION REQ. | L8: EXISTING CUS. | M8: RAVI
A9: =ROW()-1 -> 8 | B9: 46113 | C9: Eka mobility solutions | D9: Pithampur | E9: Tamil Nadu | F9: Manipulator | G9: EOT Crane, XY rail, Manipulator | I9: anil.m@ekamobility.com' | J9: QUOTATION REQ. | K9: Anil Malviya | L9: EXISTING CUS. | M9: RAVI | N9: 7-EKA MOBILITY-PITHAMPUR-05/04/26 | O9: 46116 | Q9: Quotation Sent
A10: =ROW()-1 -> 9 | B10: 46113 | C10: Cummins Generator Technologies India Pvt Ltd | D10: Ranjangoan | E10: Maharashtra | F10: EOT Crane | G10: EOT Crane of 2MT Capacity | H10: 9146185214 | I10: <sandeep.naikare@cummins.com> | J10: QUOTATION REQ. | K10: Sandeep Naikare | L10: EXISTING CUS. | M10: MALLESH
A11: =ROW()-1 -> 10 | B11: 46113 | C11: Emerson Process Management (India) Pvt. Ltd | D11: Chakan | E11: Maharashtra | F11: EOT Crane | G11: Single Girder EOT Crane of 5MT Capacity | H11: 9765559037 | I11: <Raviprasad.Savkar@Emerson.com> | J11: QUOTATION REQ. | K11: Savakar, Raviprasad | L11: EXISTING CUS. | M11: RAVI | N11: 06-EMERSON -5TSGEOT
A12: =ROW()-1 -> 11 | B12: 46113 | D12: Thane | E12: Maharashtra | F12: Goliath | G12: Goliath crane | H12: 9324210241 | I12: naveenagrawal2007@gmail.com | J12: LOST | K12: naveen agarwal | L12: TRADEINDIA | M12: VIVEK
A13: =ROW()-1 -> 12 | B13: 46113 | C13: MITTAL TRADERS | D13: Howrah | F13: EOT Crane | G13: eot cranes | H13: 9007847150 | I13: mohitmitt@gmail.com | J13: NOT RECEIVED | K13: mohit mittal | L13: TRADEINDIA | M13: VIVEK
A14: =ROW()-1 -> 13 | B14: 46113 | C14: KSB India Ltd | D14: Ahmednagar | E14: Maharashtra | F14: EOT Crane | G14: Single Girder EOT Crane of 5MT Capacity | H14: 9970951430 | I14: <Jaywant.Sutar@ksb.com> | J14: QUOTATION REQ. | K14: Sutar, Jaywant' | L14: EXISTING CUS. | M14: RAVI
A15: =ROW()-1 -> 14 | B15: 46114 | C15: Singh Fabrication | D15: Pune, Maharashtra, India | E15: Maharashtra | F15: Hoist | G15: hoist | H15: 8766460470 | I15: sshambhussingh08893@gmail.com | J15: CONTACTED | K15: Shambhu Singh | L15: INDIAMART | M15: SAKSHI
A16: =ROW()-1 -> 15 | B16: 46114 | D16: Pune, Maharashtra, India | E16: Maharashtra | F16: EOT Crane | G16: Industrial cranes | H16: 7385604099 | J16: FAKE | K16: nagesh talwar | L16: TRADEINDIA | M16: VIVEK
A17: =ROW()-1 -> 16 | B17: 46114 | D17: Barrackpore | F17: EOT Crane | G17: heavy duty hydra crane | H17: 9883612877 | J17: FAKE | K17: anand gupta | L17: TRADEINDIA | M17: VIVEK
A18: =ROW()-1 -> 17 | B18: 46114 | C18: INFINITE ENERGY PVT. LTD | D18: faridabad | E18: Haryana | F18: Jib Crane | G18: jib crane | H18: 9212084932 | J18: QUOTATION REQ. | K18: naval | L18: TRADEINDIA | M18: VIVEK
A19: =ROW()-1 -> 18 | B19: 46115 | C19: Aakruti Tooling | D19: Moi | E19: Maharashtra | F19: EOT Crane | G19: 12.5MT EOT Crane | I19: -aakrutitooling@gmail.com | J19: QUOTATION REQ. | L19: REFRENCE | M19: VIVEK | N19: 11-AAKRUTI-EOT-12.5T-MOI-05/04/26 | O19: 46117 | Q19: Quotation Sent
A20: =ROW()-1 -> 19 | B20: 46115 | C20: ENERSYS THERMAL LTD | E20: Maharashtra | F20: Others | G20: 5T & 10T Hoist | I20: enersys.pune@gmail.com | J20: QUOTATION REQ. | L20: INDIAMART | M20: VIVEK | N20: 8-ENERGYGS-HOIST -5 & 10T-04/04/26 | O20: 46116 | Q20: Quotation Sent
A21: =ROW()-1 -> 20 | B21: 46115 | C21: Application Eng. | D21: bhosari | E21: Maharashtra | F21: Others | G21: LCS SYSTEM of 500kg & 1T | I21: <applicationengg@impregseal.com> | J21: QUOTATION REQ. | L21: REFRENCE | M21: VIVEK | N21: 9-ApplicationEngg-LCS-500kg1T -05/04/26 | O21: 46116 | Q21: Quotation Sent
A22: =ROW()-1 -> 21 | B22: 46115 | C22: Aarya And Company | D22: Waluj Midc, P No 6, Cidco, Gut No 105, Aurangabad, Maharashtra, India | E22: Maharashtra | F22: Gantry Crane | G22: Portable Gantry Cranes | H22: 9960238973 | I22: chetanyelikar@yahoo.in | J22: QUOTATION REQ. | K22: Chetan Yelikar | L22: INDIAMART | M22: VIVEK
A23: =ROW()-1 -> 22 | B23: 46115 | C23: Ho Company | D23: a/p pimpale,, Indapur, Maharashtra, India | E23: Maharashtra | F23: Hoist | G23: Electric Hoists | H23: 9923625798 | I23: yuvraj_kate84@rediffmail.com | J23: QUOTATION REQ. | K23: Kate Yuvraj | L23: INDIAMART | M23: SAKSHI
A24: =ROW()-1 -> 23 | B24: 46115 | D24: Chakan, Maharashtra, India | E24: Maharashtra | F24: Hoist | G24: Wire Rope Hoist | H24: 8591226468 | J24: LOST | K24: VAISHALI | L24: INDIAMART | M24: SAKSHI
A25: =ROW()-1 -> 24 | B25: 46115 | C25: Perfect Machine Tools Corporation Limited | D25: Plot No. 36, 1st Floor, Rajendra Nagar, Sector- 5, Sahibabad, Uttar Pradesh, India | E25: Uttar Pradesh | F25: Manipulator | G25: Manipulators | H25: 9370556327 | I25: pmtdel@pmtcoltd.com | J25: NEW | K25: S.K. Kapoor | L25: INDIAMART | M25: RAVI
A26: =ROW()-1 -> 25 | B26: 46115 | D26: Coimbatore, Tamil Nadu, India | E26: Tamil Nadu | F26: Hoist | G26: 2 Ton Electric Chain Hoist | H26: 7708636022 | I26: nsnkarthik12@gmail.com | J26: NOT INTERESTED | K26: RAJENDRAN KARTHIK | L26: INDIAMART | M26: SAKSHI
A27: =ROW()-1 -> 26 | B27: 46115 | C27: A J Enterprise | D27: 01, Jani Kalan, Baghpat Road, Jani Buzurg, Near Aiter Tower, Meerut, Uttar Pradesh, India | E27: Uttar Pradesh | F27: EOT Crane | G27: Electric Overhead Crane | H27: 9997306071 | I27: gufrankhanjanimeerut@gmail.com | J27: CONTACTED | K27: Gufran Khan | L27: INDIAMART | M27: VIVEK
A28: =ROW()-1 -> 27 | B28: 46116 | C28: mohamaad safik contractor | D28: Jodhpur, Rajasthan, India | E28: Rajasthan | F28: Manipulator | G28: Overhead Mounted Manipulator | H28: 9694664945 | I28: mohmmad.aslam04@gmail.com | J28: FAKE | K28: aslam | L28: INDIAMART | M28: VIVEK
A29: =ROW()-1 -> 28 | B29: 46116 | C29: horizontal boring machine job work | D29: Rajkot, Gujarat, India | E29: Gujarat | F29: EOT Crane | G29: Single Girder Cranes | H29: 6351590630 | I29: basirboghara26@gmail.com | J29: NOT INTERESTED | K29: Arsh Boghara | L29: INDIAMART | M29: VIVEK
A30: =ROW()-1 -> 29 | B30: 46116 | C30: Sri Mahalakshmi Engineering Works | D30: 5-35/227,Shakthi puram,Prashanthi nagar,kukatpally, Hyderabad, Telangana, India | E30: Telangana | F30: Hoist | G30: Heavy Duty Wire Rope Hoist | H30: 9440860225 | I30: srimahalakshmi216@gmail.com | J30: NOT RECEIVED | K30: Santhosh | L30: INDIAMART | M30: SAKSHI
A31: =ROW()-1 -> 30 | B31: 46116 | C31: Andriya Shipping | D31: Thoothukudi, Tamil Nadu, India | E31: Tamil Nadu | F31: Jib Crane | G31: Pillar Mounted Jib Crane | H31: 7397256036 | I31: andriyashipping@gmail.com | J31: FAKE | K31: kaushik | L31: INDIAMART | M31: VIVEK
A32: =ROW()-1 -> 31 | B32: 46116 | C32: Universal Marketing Services | E32: Uttar Pradesh | F32: Hoist | G32: 3 Ton Electric Wire Rope Hoist | H32: 9443114544 | I32: umsscales@gmail.com | J32: NOT INTERESTED | K32: Ahilan Natarajan | L32: INDIAMART | M32: SAKSHI
A33: =ROW()-1 -> 32 | B33: 46116 | E33: Uttar Pradesh | F33: Hoist | G33: Electric Chain Hoist | H33: 9850103500 | I33: coolatul1994@gmail.com | J33: NOT RECEIVED | K33: atul | L33: INDIAMART | M33: SAKSHI
A34: =ROW()-1 -> 33 | B34: 46116 | D34: mumbai | E34: Uttar Pradesh | F34: Hoist | G34: hoist | H34: 9561900219 | I34: arjunkurhade66967@gmail.com | J34: LOST | K34: arjun | L34: INDIAMART | M34: SAKSHI
A35: =ROW()-1 -> 34 | B35: 46116 | C35: Shiv Enterprises | D35: H No 593,Dandavate Galli,Dandavate Galli,Vhanali,Kolhapur, Kolhapur, Maharashtra, India | E35: Maharashtra | F35: Hoist | G35: 1 Ton Electric Chain Hoist | H35: 9158772627 | I35: arvinddandwate2@gmail.com | J35: QUOTATION REQ. | K35: anita | L35: INDIAMART | M35: SAKSHI
A36: =ROW()-1 -> 35 | B36: 46116 | C36: S B Engineering | D36: 360, Shivaling Colony, Brahma Nagar, Belagavi, Karnataka, India | E36: Karnatka | F36: Hoist | G36: Electric Hoists | H36: 9606739416 | I36: shubhamwadekar35968@gmail.com | J36: NOT INTERESTED | K36: shubham | L36: INDIAMART | M36: SAKSHI
A37: =ROW()-1 -> 36 | B37: 46117 | C37: CLF PROJECTS PVT LTD | D37: Pune | E37: Maharashtra | F37: EOT Crane | G37: DG EOT Crane of 15/5MT Capacity | I37: purchase.infra@clfprojects.com' | J37: QUOTATION REQ. | L37: REFRENCE | M37: MALLESH | N37: 10-CLF PROJECTS-15/5T-05/041/26 | O37: 46117 | Q37: Quotation Sent
A38: =ROW()-1 -> 37 | B38: 46118 | C38: PMI Coaches Pvt Ltd | D38: Pune, Maharashtra, India | E38: Maharashtra | F38: Jib Crane | G38: Pillar Mounted Jib Crane | H38: 9158899611 | I38: AVINASHJAIN59@GMAIL.COM | J38: CONTACTED | K38: avinash jain | L38: INDIAMART | M38: VIVEK
A39: =ROW()-1 -> 38 | B39: 46118 | C39: S. H. Engineers | D39: Sector No. D-9/10, Industrial Estate, Baramati, Maharashtra, India | E39: Maharashtra | F39: Hoist | G39: Electric Wire Rope Hoist | H39: 9765356786 | I39: waseem.shikalkar@gmail.com | J39: NOT RECEIVED | K39: Waseem Shikalkar | L39: INDIAMART | M39: SAKSHI
A40: =ROW()-1 -> 39 | B40: 46118 | C40: Vertex Elevators India | D40: Office No 167, 1st Floor,, Pune, Maharashtra, India | E40: Maharashtra | F40: Hoist | G40: Electric Chain Hoist | H40: 7776076665 | J40: SITE VISIT REQ. | K40: Pramod Kinge | L40: INDIAMART | M40: SAKSHI
...

Sheet Dashboard
B2: SALES DEPARTMENT | W2: =TODAY() -> 46132
B3: TOTAL NO LEADS | D3: TODAY | E3: YESTURDAY | F3: DAY BRFORE | H3: TOTAL VALUE: | I3: PO RECEIVED | K3: YEAR | L3: MONTH | N3: NEW LEADS
B4: =Table5[[#Totals],[NOS]] -> 125 | D4: ='DATA SHEET'!L11 -> 0 | E4: ='DATA SHEET'!L12 -> 0 | F4: ='DATA SHEET'!L17 -> 0 | H4: ='DATA SHEET'!L14 -> 450000 | I4: ='DATA SHEET'!L15 -> 0 | K4: ='DATA SHEET'!L16 -> 125 | L4: ='DATA SHEET'!L13 -> 125 | N4: ='DATA SHEET'!H11 -> 17

Sheet DATA SHEET
C2: STATES | D2: No | G2: SALES OVERVIEW | K2: LEAD OWNER | L2: NO | N2: 📊 Weekly Dashboard (Mon–Sun) | R2: 📊 Yearly Dashboard (Jan–Dec 2026)
C3: Andhra Pradesh | D3: =COUNTIF('Lead Tracker'!E:E,"Andhra Pradesh") -> 1 | G3: REFRENCE | H3: =COUNTIF('Lead Tracker'!L:L, G3) -> 5 | K3: MALLESH | L3: =COUNTIF('Lead Tracker'!M:M, K3) -> 6 | N3: Day | O3: NOS | P3: Amount Formula | R3: Month | S3: NOS | T3: Amount Formula
C4: Arunachal Pradesh | D4: =COUNTIF('Lead Tracker'!E:E,"Andhra Pradesh") -> 1 | G4: EXISTING CUS. | H4: =COUNTIF('Lead Tracker'!L:L, G4) -> 9 | K4: RAVI | L4: =COUNTIF('Lead Tracker'!M:M, K4) -> 18 | N4: Monday | O4: =COUNTIFS('Lead Tracker'!B:B, TODAY()-WEEKDAY(TODAY(),2)+1) -> 0 | P4: =SUMIFS('Lead Tracker'!P:P, 'Lead Tracker'!B:B, TODAY()-WEEKDAY(TODAY(),2)+1) -> 0 | R4: 46113 | S4: =COUNTIFS('Lead Tracker'!B:B,">="&DATE(2026,4,1),'Lead Tracker'!B:B,"<="&DATE(2026,4,30)) -> 125 | T4: =SUMIFS('Lead Tracker'!P:P,'Lead Tracker'!B:B,">="&DATE(2026,4,1),'Lead Tracker'!B:B,"<="&DATE(2026,4,30)) -> 450000
C5: Assam | D5: =COUNTIF('Lead Tracker'!E:E,"Assam") -> 2 | G5: MAIL | H5: =COUNTIF('Lead Tracker'!L:L, G5) -> 22 | K5: HARSH | L5: =COUNTIF('Lead Tracker'!M:M, K5) -> 2 | N5: Tuesday | O5: =COUNTIFS('Lead Tracker'!B:B, TODAY()-WEEKDAY(TODAY(),2)+2) -> 0 | P5: =SUMIFS('Lead Tracker'!P:P, 'Lead Tracker'!B:B, TODAY()-WEEKDAY(TODAY(),2)+2) -> 0 | R5: 46143 | S5: =COUNTIFS('Lead Tracker'!B:B,">="&DATE(2026,5,1),'Lead Tracker'!B:B,"<="&DATE(2026,5,31)) -> 0 | T5: =SUMIFS('Lead Tracker'!P:P,'Lead Tracker'!B:B,">="&DATE(2026,5,1),'Lead Tracker'!B:B,"<="&DATE(2026,5,31)) -> 0
C6: Bihar | D6: =COUNTIF('Lead Tracker'!E:E,"Bihar") -> 0 | G6: INDIAMART | H6: =COUNTIF('Lead Tracker'!L:L, G6) -> 58 | K6: VIVEK | L6: =COUNTIF('Lead Tracker'!M:M, K6) -> 61 | N6: Wednesday | O6: =COUNTIFS('Lead Tracker'!B:B, TODAY()-WEEKDAY(TODAY(),2)+3) -> 0 | P6: =SUMIFS('Lead Tracker'!P:P, 'Lead Tracker'!B:B, TODAY()-WEEKDAY(TODAY(),2)+3) -> 0 | R6: 46174 | S6: =COUNTIFS('Lead Tracker'!B:B,">="&DATE(2026,6,1),'Lead Tracker'!B:B,"<="&DATE(2026,6,30)) -> 0 | T6: =SUMIFS('Lead Tracker'!P:P,'Lead Tracker'!B:B,">="&DATE(2026,6,1),'Lead Tracker'!B:B,"<="&DATE(2026,6,30)) -> 0
C7: Chhattisgarh | D7: =COUNTIF('Lead Tracker'!E:E,"Chhattisgarh") -> 1 | G7: OUT SOURCE | H7: =COUNTIF('Lead Tracker'!L:L, G7) -> 2 | K7: SAKSHI | L7: =COUNTIF('Lead Tracker'!M:M, K7) -> 36 | N7: Thursday | O7: =COUNTIFS('Lead Tracker'!B:B, TODAY()-WEEKDAY(TODAY(),2)+4) -> 0 | P7: =SUMIFS('Lead Tracker'!P:P, 'Lead Tracker'!B:B, TODAY()-WEEKDAY(TODAY(),2)+4) -> 0 | R7: 46204 | S7: =COUNTIFS('Lead Tracker'!B:B,">="&DATE(2026,7,1),'Lead Tracker'!B:B,"<="&DATE(2026,7,31)) -> 0 | T7: =SUMIFS('Lead Tracker'!P:P,'Lead Tracker'!B:B,">="&DATE(2026,7,1),'Lead Tracker'!B:B,"<="&DATE(2026,7,31)) -> 0
C8: Goa | D8: =COUNTIF('Lead Tracker'!E:E,"Goa") -> 0 | G8: TRADEINDIA | H8: =COUNTIF('Lead Tracker'!L:L, G8) -> 29 | N8: Friday | O8: =COUNTIFS('Lead Tracker'!B:B, TODAY()-WEEKDAY(TODAY(),2)+5) -> 0 | P8: =SUMIFS('Lead Tracker'!P:P, 'Lead Tracker'!B:B, TODAY()-WEEKDAY(TODAY(),2)+5) -> 0 | R8: 46235 | S8: =COUNTIFS('Lead Tracker'!B:B,">="&DATE(2026,8,1),'Lead Tracker'!B:B,"<="&DATE(2026,8,31)) -> 0 | T8: =SUMIFS('Lead Tracker'!P:P,'Lead Tracker'!B:B,">="&DATE(2026,8,1),'Lead Tracker'!B:B,"<="&DATE(2026,8,31)) -> 0
C9: Gujarat | D9: =COUNTIF('Lead Tracker'!E:E,"Gujarat") -> 2 | K9: DASH | N9: Saturday | O9: =COUNTIFS('Lead Tracker'!B:B, TODAY()-WEEKDAY(TODAY(),2)+6) -> 0 | P9: =SUMIFS('Lead Tracker'!P:P, 'Lead Tracker'!B:B, TODAY()-WEEKDAY(TODAY(),2)+6) -> 0 | R9: 46266 | S9: =COUNTIFS('Lead Tracker'!B:B,">="&DATE(2026,9,1),'Lead Tracker'!B:B,"<="&DATE(2026,9,30)) -> 0 | T9: =SUMIFS('Lead Tracker'!P:P,'Lead Tracker'!B:B,">="&DATE(2026,9,1),'Lead Tracker'!B:B,"<="&DATE(2026,9,30)) -> 0
C10: Haryana | D10: =COUNTIF('Lead Tracker'!E:E,"Haryana") -> 2 | G10: INQUIRY | H10: NOS | K10: LEADS DATA | L10: VALUE | N10: Sunday | O10: =COUNTIFS('Lead Tracker'!B:B, TODAY()-WEEKDAY(TODAY(),2)+7) -> 0 | P10: =SUMIFS('Lead Tracker'!P:P, 'Lead Tracker'!B:B, TODAY()-WEEKDAY(TODAY(),2)+7) -> 0 | R10: 46296 | S10: =COUNTIFS('Lead Tracker'!B:B,">="&DATE(2026,10,1),'Lead Tracker'!B:B,"<="&DATE(2026,10,31)) -> 0 | T10: =SUMIFS('Lead Tracker'!P:P,'Lead Tracker'!B:B,">="&DATE(2026,10,1),'Lead Tracker'!B:B,"<="&DATE(2026,10,31)) -> 0
C11: Himachal Pradesh | D11: =COUNTIF('Lead Tracker'!E:E,"Himachal Pradesh") -> 0 | G11: NEW | H11: =COUNTIF('Lead Tracker'!J:J, G11) -> 17 | K11: TODAY | L11: =COUNTIF('Lead Tracker'!B:B, TODAY()) -> 0 | N11: =SUBTOTAL(109,N4:N10) -> 0 | O11: =SUBTOTAL(109,O4:O10) -> 0 | P11: =SUBTOTAL(109,P4:P10) -> 0 | R11: 46327 | S11: =COUNTIFS('Lead Tracker'!B:B,">="&DATE(2026,11,1),'Lead Tracker'!B:B,"<="&DATE(2026,11,30)) -> 0 | T11: =SUMIFS('Lead Tracker'!P:P,'Lead Tracker'!B:B,">="&DATE(2026,11,1),'Lead Tracker'!B:B,"<="&DATE(2026,11,30)) -> 0
C12: Jharkhand | D12: =COUNTIF('Lead Tracker'!E:E,"Jharkhand") -> 0 | G12: WIN | H12: =COUNTIF('Lead Tracker'!J:J, G12) -> 2 | K12: YESTURDAY | L12: =COUNTIF('Lead Tracker'!B:B, TODAY()-1) -> 0 | R12: 46357 | S12: =COUNTIFS('Lead Tracker'!B:B,">="&DATE(2026,12,1),'Lead Tracker'!B:B,"<="&DATE(2026,12,31)) -> 0 | T12: =SUMIFS('Lead Tracker'!P:P,'Lead Tracker'!B:B,">="&DATE(2026,12,1),'Lead Tracker'!B:B,"<="&DATE(2026,12,31)) -> 0
C13: Telangana | D13: =COUNTIF('Lead Tracker'!E:E,"Telangana") -> 2 | G13: LOST | H13: =COUNTIF('Lead Tracker'!J:J, G13) -> 5 | K13: MONTHS | L13: =COUNTIFS('Lead Tracker'!B:B, ">="&EOMONTH(TODAY(),-1)+1, 'Lead Tracker'!B:B, "<="&EOMONTH(TODAY(),0)) -> 125 | R13: 46388
C14: Kerala | D14: =COUNTIF('Lead Tracker'!E:E,"Kerala") -> 0 | G14: CONTACTED | H14: =COUNTIF('Lead Tracker'!J:J, G14) -> 10 | K14: TOTAL VALUE | L14: =SUM(T4:T16) -> 450000 | R14: 46419
C15: Madhya Pradesh | D15: =COUNTIF('Lead Tracker'!E:E,"Madhya Pradesh") -> 1 | G15: NOT INTERESTED | H15: =COUNTIF('Lead Tracker'!J:J, G15) -> 14 | K15: PO RECEIVED | L15: =SUMIFS('Lead Tracker'!P:P, 'Lead Tracker'!Q:Q, "PO Received") -> 0 | R15: 46447
C16: Maharashtra | D16: =COUNTIF('Lead Tracker'!E:E,"Maharashtra") -> 78 | G16: SITE VISIT REQ. | H16: =COUNTIF('Lead Tracker'!J:J, G16) -> 1 | K16: YEAR | L16: =SUBTOTAL(109,S4:S12) -> 125 | R16: 46478
C17: Manipur | D17: =COUNTIF('Lead Tracker'!E:E,"Manipur") -> 0 | G17: QUOTATION REQ. | H17: =COUNTIF('Lead Tracker'!J:J, G17) -> 42 | K17: DAY BEFORE YESTURDAY | L17: =COUNTIF('Lead Tracker'!B:B, TODAY()-2) -> 0 | S17: =SUBTOTAL(109,S4:S16) -> 125 | T17: =SUBTOTAL(109,T4:T16) -> 450000
C18: Meghalaya | D18: =COUNTIF('Lead Tracker'!E:E,"Meghalaya") -> 0 | G18: NOT RECEIVED | H18: =COUNTIF('Lead Tracker'!J:J, G18) -> 14
C19: Karnatka | D19: =COUNTIF('Lead Tracker'!E:E,"Karnatka") -> 3 | G19: FAKE | H19: =COUNTIF('Lead Tracker'!J:J, G19) -> 16 | K19: CRANE TYPES
C20: Mizoram | D20: =COUNTIF('Lead Tracker'!E:E,"Mizoram") -> 0 | G20: FULFILLED | H20: =COUNTIF('Lead Tracker'!J:J, G20) -> 2 | K20: TYPES OF CRANES | L20: NOS
C21: Nagaland | D21: =COUNTIF('Lead Tracker'!E:E,"Nagaland") -> 0 | G21: QUOTATION SHARED | H21: =COUNTIF('Lead Tracker'!J:J, G21) -> 2 | K21: Modification | L21: =COUNTIF('Lead Tracker'!F:F, K21) -> 0
C22: Odisha | D22: =COUNTIF('Lead Tracker'!E:E,"Odisha") -> 0 | K22: LCS | L22: =COUNTIF('Lead Tracker'!F:F, K22) -> 3
C23: Punjab | D23: =COUNTIF('Lead Tracker'!E:E,"Punjab") -> 4 | K23: Monorail | L23: =COUNTIF('Lead Tracker'!F:F, K23) -> 0
C24: Rajasthan | D24: =COUNTIF('Lead Tracker'!E:E,"Rajasthan") -> 2 | G24: QUOTATIONS | K24: EOT Crane | L24: =COUNTIF('Lead Tracker'!F:F, K24) -> 30
C25: Sikkim | D25: =COUNTIF('Lead Tracker'!E:E,"Sikkim") -> 0 | G25: Quotation Status | H25: NOS | K25: Jib Crane | L25: =COUNTIF('Lead Tracker'!F:F, K25) -> 23
C26: Tamil Nadu | D26: =COUNTIF('Lead Tracker'!E:E,"Tamil Nadu") -> 5 | G26: Quotation Sent | H26: =COUNTIF('Lead Tracker'!Q:Q, G26) -> 12 | K26: Hoist | L26: =COUNTIF('Lead Tracker'!F:F, K26) -> 43
C27: Tripura | D27: =COUNTIF('Lead Tracker'!E:E,"Tripura") -> 0 | G27: Clarification Pending | H27: =COUNTIF('Lead Tracker'!Q:Q, G27) -> 0 | K27: Gantry Crane | L27: =COUNTIF('Lead Tracker'!F:F, K27) -> 7
C28: Uttar Pradesh | D28: =COUNTIF('Lead Tracker'!E:E,"Uttar Pradesh") -> 12 | G28: Discussion Ongoing | H28: =COUNTIF('Lead Tracker'!Q:Q, G28) -> 0 | K28: Manipulator | L28: =COUNTIF('Lead Tracker'!F:F, K28) -> 5
C29: Uttarakhand | D29: =COUNTIF('Lead Tracker'!E:E,"Uttarakhand") -> 0 | G29: On Hold | H29: =COUNTIF('Lead Tracker'!Q:Q, G29) -> 0 | K29: Scissor Lifter | L29: =COUNTIF('Lead Tracker'!F:F, K29) -> 0
C30: West Bengal | D30: =COUNTIF('Lead Tracker'!E:E,"West Bengal") -> 0 | G30: PO Received | H30: =COUNTIF('Lead Tracker'!Q:Q, G30) -> 2 | K30: Others | L30: =COUNTIF('Lead Tracker'!F:F, K30) -> 12
C31: Others | D31: =COUNTIF('Lead Tracker'!E:E,"Others") -> 0 | G31: Closed | H31: =COUNTIF('Lead Tracker'!Q:Q, G31) -> 0 | K31: Underslung | L31: =COUNTIF('Lead Tracker'!F:F, K31) -> 0
C32: International | D32: =COUNTIF('Lead Tracker'!E:E,"International") -> 0 | G32: In Progress | H32: =COUNTIF('Lead Tracker'!Q:Q, G32) -> 0 | K32: Goliath | L32: =COUNTIF('Lead Tracker'!F:F, K32) -> 1
C33: TOTAL LEADS | D33: =SUBTOTAL(109,Table4[No]) -> 116 | G33: NA | H33: =COUNTIF('Lead Tracker'!Q:Q, G33) -> 0
G35: =TODAY() -> 46132 | K35: =G35 -> 46132
G36: INQUIRY | H36: NOS | K36: SALES OVERVIEW
G37: NEW | H37: =COUNTIFS('Lead Tracker'!J:J, G37, 'Lead Tracker'!B:B, $G$35) -> 0 | K37: REFRENCE | L37: =COUNTIFS('Lead Tracker'!L:L, G3, 'Lead Tracker'!B:B, $G$35) -> 0
G38: WIN | H38: =COUNTIFS('Lead Tracker'!J:J, G38, 'Lead Tracker'!B:B, $G$35) -> 0 | K38: EXISTING CUS. | L38: =COUNTIFS('Lead Tracker'!L:L, G4, 'Lead Tracker'!B:B, $G$35) -> 0
G39: LOST | H39: =COUNTIFS('Lead Tracker'!J:J, G39, 'Lead Tracker'!B:B, $G$35) -> 0 | K39: MAIL | L39: =COUNTIFS('Lead Tracker'!L:L, G5, 'Lead Tracker'!B:B, $G$35) -> 0
G40: CONTACTED | H40: =COUNTIFS('Lead Tracker'!J:J, G40, 'Lead Tracker'!B:B, $G$35) -> 0 | K40: INDIAMART | L40: =COUNTIFS('Lead Tracker'!L:L, G6, 'Lead Tracker'!B:B, $G$35) -> 0
G41: NOT INTERESTED | H41: =COUNTIFS('Lead Tracker'!J:J, G41, 'Lead Tracker'!B:B, $G$35) -> 0 | K41: OUT SOURCE | L41: =COUNTIFS('Lead Tracker'!L:L, G7, 'Lead Tracker'!B:B, $G$35) -> 0
G42: SITE VISIT REQ. | H42: =COUNTIFS('Lead Tracker'!J:J, G42, 'Lead Tracker'!B:B, $G$35) -> 0 | K42: TRADEINDIA | L42: =COUNTIFS('Lead Tracker'!L:L, G8, 'Lead Tracker'!B:B, $G$35) -> 0
...

Sheet SUMMARY
D2: DATA SHEET
D3: LEAD SOURCES | F3: NEW | G3: WIN | H3: LOST | I3: CONTACTED | J3: NOT INTERESTED | K3: SITE VISIT REQ. | L3: QUOTATION REQ. | M3: NOT RECEIVED | N3: FAKE | O3: FULFILLED | P3: QUOTATION SHARED
D4: DATA | E4: =Table5[[#Totals],[NOS]] -> 125 | F4: =COUNTIF('Lead Tracker'!$J:$J,F3) -> 17 | G4: =COUNTIF('Lead Tracker'!$J:$J,G3) -> 2 | H4: =COUNTIF('Lead Tracker'!$J:$J,H3) -> 5 | I4: =COUNTIF('Lead Tracker'!$J:$J,I3) -> 10 | J4: =COUNTIF('Lead Tracker'!$J:$J,J3) -> 14 | K4: =COUNTIF('Lead Tracker'!$J:$J,K3) -> 1 | L4: =COUNTIF('Lead Tracker'!$J:$J,L3) -> 42 | M4: =COUNTIF('Lead Tracker'!$J:$J,M3) -> 14 | ... P4: =COUNTIF('Lead Tracker'!$J:$J,P3) -> 2
D5: REFRENCE | E5: =COUNTIF('Lead Tracker'!L:L, D5) -> 5 | F5: =COUNTIFS('Lead Tracker'!$L:$L,D5,'Lead Tracker'!$J:$J,$F$3) -> 0 | G5: =COUNTIFS('Lead Tracker'!$L:$L,D5,'Lead Tracker'!$J:$J,$G$3) -> 0 | H5: =COUNTIFS('Lead Tracker'!$L:$L,D5,'Lead Tracker'!$J:$J,$H$3) -> 0 | I5: =COUNTIFS('Lead Tracker'!$L:$L,D5,'Lead Tracker'!$J:$J,$I$3) -> 0 | J5: =COUNTIFS('Lead Tracker'!$L:$L,D5,'Lead Tracker'!$J:$J,$J$3) -> 0 | K5: =COUNTIFS('Lead Tracker'!$L:$L,D5,'Lead Tracker'!$J:$J,$K$3) -> 0 | L5: =COUNTIFS('Lead Tracker'!$L:$L,D5,'Lead Tracker'!$J:$J,$L$3) -> 5 | M5: =COUNTIFS('Lead Tracker'!$L:$L,D5,'Lead Tracker'!$J:$J,$M$3) -> 0 | N5: =COUNTIFS('Lead Tracker'!$L:$L,D5,'Lead Tracker'!$J:$J,$N$3) -> 0 | O5: =COUNTIFS('Lead Tracker'!$L:$L,D5,'Lead Tracker'!$J:$J,$O$3) -> 0 | P5: =COUNTIFS('Lead Tracker'!$L:$L,D5,'Lead Tracker'!$J:$J,$P$3) -> 0
D6: EXISTING CUS. | E6: =COUNTIF('Lead Tracker'!L:L, D6) -> 9 | F6: =COUNTIFS('Lead Tracker'!$L:$L,D6,'Lead Tracker'!$J:$J,$F$3) -> 0 | G6: =COUNTIFS('Lead Tracker'!$L:$L,D6,'Lead Tracker'!$J:$J,$G$3) -> 1 | H6: =COUNTIFS('Lead Tracker'!$L:$L,D6,'Lead Tracker'!$J:$J,$H$3) -> 0 | I6: =COUNTIFS('Lead Tracker'!$L:$L,D6,'Lead Tracker'!$J:$J,$I$3) -> 0 | J6: =COUNTIFS('Lead Tracker'!$L:$L,D6,'Lead Tracker'!$J:$J,$J$3) -> 0 | K6: =COUNTIFS('Lead Tracker'!$L:$L,D6,'Lead Tracker'!$J:$J,$K$3) -> 0 | L6: =COUNTIFS('Lead Tracker'!$L:$L,D6,'Lead Tracker'!$J:$J,$L$3) -> 8 | M6: =COUNTIFS('Lead Tracker'!$L:$L,D6,'Lead Tracker'!$J:$J,$M$3) -> 0 | N6: =COUNTIFS('Lead Tracker'!$L:$L,D6,'Lead Tracker'!$J:$J,$N$3) -> 0 | O6: =COUNTIFS('Lead Tracker'!$L:$L,D6,'Lead Tracker'!$J:$J,$O$3) -> 0 | P6: =COUNTIFS('Lead Tracker'!$L:$L,D6,'Lead Tracker'!$J:$J,$P$3) -> 0
D7: MAIL | E7: =COUNTIF('Lead Tracker'!L:L, D7) -> 22 | F7: =COUNTIFS('Lead Tracker'!$L:$L,D7,'Lead Tracker'!$J:$J,$F$3) -> 2 | G7: =COUNTIFS('Lead Tracker'!$L:$L,D7,'Lead Tracker'!$J:$J,$G$3) -> 1 | H7: =COUNTIFS('Lead Tracker'!$L:$L,D7,'Lead Tracker'!$J:$J,$H$3) -> 0 | I7: =COUNTIFS('Lead Tracker'!$L:$L,D7,'Lead Tracker'!$J:$J,$I$3) -> 1 | J7: =COUNTIFS('Lead Tracker'!$L:$L,D7,'Lead Tracker'!$J:$J,$J$3) -> 0 | K7: =COUNTIFS('Lead Tracker'!$L:$L,D7,'Lead Tracker'!$J:$J,$K$3) -> 0 | L7: =COUNTIFS('Lead Tracker'!$L:$L,D7,'Lead Tracker'!$J:$J,$L$3) -> 16 | M7: =COUNTIFS('Lead Tracker'!$L:$L,D7,'Lead Tracker'!$J:$J,$M$3) -> 0 | N7: =COUNTIFS('Lead Tracker'!$L:$L,D7,'Lead Tracker'!$J:$J,$N$3) -> 0 | O7: =COUNTIFS('Lead Tracker'!$L:$L,D7,'Lead Tracker'!$J:$J,$O$3) -> 0 | P7: =COUNTIFS('Lead Tracker'!$L:$L,D7,'Lead Tracker'!$J:$J,$P$3) -> 2
D8: INDIAMART | E8: =COUNTIF('Lead Tracker'!L:L, D8) -> 58 | F8: =COUNTIFS('Lead Tracker'!$L:$L,D8,'Lead Tracker'!$J:$J,$F$3) -> 9 | G8: =COUNTIFS('Lead Tracker'!$L:$L,D8,'Lead Tracker'!$J:$J,$G$3) -> 0 | H8: =COUNTIFS('Lead Tracker'!$L:$L,D8,'Lead Tracker'!$J:$J,$H$3) -> 3 | I8: =COUNTIFS('Lead Tracker'!$L:$L,D8,'Lead Tracker'!$J:$J,$I$3) -> 7 | J8: =COUNTIFS('Lead Tracker'!$L:$L,D8,'Lead Tracker'!$J:$J,$J$3) -> 10 | K8: =COUNTIFS('Lead Tracker'!$L:$L,D8,'Lead Tracker'!$J:$J,$K$3) -> 1 | L8: =COUNTIFS('Lead Tracker'!$L:$L,D8,'Lead Tracker'!$J:$J,$L$3) -> 10 | M8: =COUNTIFS('Lead Tracker'!$L:$L,D8,'Lead Tracker'!$J:$J,$M$3) -> 9 | N8: =COUNTIFS('Lead Tracker'!$L:$L,D8,'Lead Tracker'!$J:$J,$N$3) -> 9 | O8: =COUNTIFS('Lead Tracker'!$L:$L,D8,'Lead Tracker'!$J:$J,$O$3) -> 0 | P8: =COUNTIFS('Lead Tracker'!$L:$L,D8,'Lead Tracker'!$J:$J,$P$3) -> 0
D9: OUT SOURCE | E9: =COUNTIF('Lead Tracker'!L:L, D9) -> 2 | F9: =COUNTIFS('Lead Tracker'!$L:$L,D9,'Lead Tracker'!$J:$J,$F$3) -> 0 | G9: =COUNTIFS('Lead Tracker'!$L:$L,D9,'Lead Tracker'!$J:$J,$G$3) -> 0 | H9: =COUNTIFS('Lead Tracker'!$L:$L,D9,'Lead Tracker'!$J:$J,$H$3) -> 0 | I9: =COUNTIFS('Lead Tracker'!$L:$L,D9,'Lead Tracker'!$J:$J,$I$3) -> 1 | J9: =COUNTIFS('Lead Tracker'!$L:$L,D9,'Lead Tracker'!$J:$J,$J$3) -> 0 | K9: =COUNTIFS('Lead Tracker'!$L:$L,D9,'Lead Tracker'!$J:$J,$K$3) -> 0 | L9: =COUNTIFS('Lead Tracker'!$L:$L,D9,'Lead Tracker'!$J:$J,$L$3) -> 1 | M9: =COUNTIFS('Lead Tracker'!$L:$L,D9,'Lead Tracker'!$J:$J,$M$3) -> 0 | N9: =COUNTIFS('Lead Tracker'!$L:$L,D9,'Lead Tracker'!$J:$J,$N$3) -> 0 | O9: =COUNTIFS('Lead Tracker'!$L:$L,D9,'Lead Tracker'!$J:$J,$O$3) -> 0 | P9: =COUNTIFS('Lead Tracker'!$L:$L,D9,'Lead Tracker'!$J:$J,$P$3) -> 0
D10: TRADEINDIA | E10: =COUNTIF('Lead Tracker'!L:L, D10) -> 29 | F10: =COUNTIFS('Lead Tracker'!$L:$L,D10,'Lead Tracker'!$J:$J,$F$3) -> 6 | G10: =COUNTIFS('Lead Tracker'!$L:$L,D10,'Lead Tracker'!$J:$J,$G$3) -> 0 | H10: =COUNTIFS('Lead Tracker'!$L:$L,D10,'Lead Tracker'!$J:$J,$H$3) -> 2 | I10: =COUNTIFS('Lead Tracker'!$L:$L,D10,'Lead Tracker'!$J:$J,$I$3) -> 1 | J10: =COUNTIFS('Lead Tracker'!$L:$L,D10,'Lead Tracker'!$J:$J,$J$3) -> 4 | K10: =COUNTIFS('Lead Tracker'!$L:$L,D10,'Lead Tracker'!$J:$J,$K$3) -> 0 | L10: =COUNTIFS('Lead Tracker'!$L:$L,D10,'Lead Tracker'!$J:$J,$L$3) -> 2 | M10: =COUNTIFS('Lead Tracker'!$L:$L,D10,'Lead Tracker'!$J:$J,$M$3) -> 5 | N10: =COUNTIFS('Lead Tracker'!$L:$L,D10,'Lead Tracker'!$J:$J,$N$3) -> 7 | O10: =COUNTIFS('Lead Tracker'!$L:$L,D10,'Lead Tracker'!$J:$J,$O$3) -> 2 | P10: =COUNTIFS('Lead Tracker'!$L:$L,D10,'Lead Tracker'!$J:$J,$P$3) -> 0
D12: 46113
D13: LEAD SOURCES | F13: NEW | G13: WIN | H13: LOST | I13: CONTACTED | J13: NOT INTERESTED | K13: SITE VISIT REQ. | L13: QUOTATION REQ. | M13: NOT RECEIVED | N13: FAKE | O13: FULFILLED | P13: QUOTATION SHARED | R13: =D12 -> 46113
D14: DATA | E14: =COUNTIFS('Lead Tracker'!$B:$B,">="&EOMONTH($D$12,-1)+1, 'Lead Tracker'!$B:$B,"<"&EOMONTH($D$12,0)+1) -> 125 | F14: =COUNTIFS( 'Lead Tracker'!$J:$J,F13, 'Lead Tracker'!$B:$B,">="&EOMONTH($D$12,-1)+1, 'Lead Tracker'!$B:$B,"<"&EOMONTH($D$12,0)+1 ) -> 17 | G14: =COUNTIFS( 'Lead Tracker'!$J:$J,G13, 'Lead Tracker'!$B:$B,">="&EOMONTH($D$12,-1)+1, 'Lead Tracker'!$B:$B,"<"&EOMONTH($D$12,0)+1 ) -> 2 | H14: =COUNTIFS( 'Lead Tracker'!$J:$J,H13, 'Lead Tracker'!$B:$B,">="&EOMONTH($D$12,-1)+1, 'Lead Tracker'!$B:$B,"<"&EOMONTH($D$12,0)+1 ) -> 5 | I14: =COUNTIFS( 'Lead Tracker'!$J:$J,I13, 'Lead Tracker'!$B:$B,">="&EOMONTH($D$12,-1)+1, 'Lead Tracker'!$B:$B,"<"&EOMONTH($D$12,0)+1 ) -> 10 | J14: =COUNTIFS( 'Lead Tracker'!$J:$J,J13, 'Lead Tracker'!$B:$B,">="&EOMONTH($D$12,-1)+1, 'Lead Tracker'!$B:$B,"<"&EOMONTH($D$12,0)+1 ) -> 14 | K14: =COUNTIFS( 'Lead Tracker'!$J:$J,K13, 'Lead Tracker'!$B:$B,">="&EOMONTH($D$12,-1)+1, 'Lead Tracker'!$B:$B,"<"&EOMONTH($D$12,0)+1 ) -> 1 | L14: =COUNTIFS( 'Lead Tracker'!$J:$J,L13, 'Lead Tracker'!$B:$B,">="&EOMONTH($D$12,-1)+1, 'Lead Tracker'!$B:$B,"<"&EOMONTH($D$12,0)+1 ) -> 42 | M14: =COUNTIFS( 'Lead Tracker'!$J:$J,M13, 'Lead Tracker'!$B:$B,">="&EOMONTH($D$12,-1)+1, 'Lead Tracker'!$B:$B,"<"&EOMONTH($D$12,0)+1 ) -> 14 | ... P14: =COUNTIFS( 'Lead Tracker'!$J:$J,P13, 'Lead Tracker'!$B:$B,">="&EOMONTH($D$12,-1)+1, 'Lead Tracker'!$B:$B,"<"&EOMONTH($D$12,0)+1 ) -> 2
D15: REFRENCE | E15: =COUNTIFS( 'Lead Tracker'!L:L,D15, 'Lead Tracker'!B:B,">="&EOMONTH($D$12,-1)+1, 'Lead Tracker'!B:B,"<"&EOMONTH($D$12,0)+1 ) -> 5 | F15: =COUNTIFS( 'Lead Tracker'!$L:$L,D15, 'Lead Tracker'!$J:$J,$F$3, 'Lead Tracker'!$B:$B,">="&EOMONTH($D$12,-1)+1, 'Lead Tracker'!$B:$B,"<"&EOMONTH($D$12,0)+1 ) -> 0 | G15: =COUNTIFS( 'Lead Tracker'!$L:$L,D15, 'Lead Tracker'!$J:$J,$G$3, 'Lead Tracker'!$B:$B,">="&EOMONTH($D$12,-1)+1, 'Lead Tracker'!$B:$B,"<"&EOMONTH($D$12,0)+1 ) -> 0 | H15: =COUNTIFS( 'Lead Tracker'!$L:$L,D15, 'Lead Tracker'!$J:$J,$H$3, 'Lead Tracker'!$B:$B,">="&EOMONTH($D$12,-1)+1, 'Lead Tracker'!$B:$B,"<"&EOMONTH($D$12,0)+1 ) -> 0 | I15: =COUNTIFS('Lead Tracker'!$L:$L,D15,'Lead Tracker'!$J:$J,$I$3,'Lead Tracker'!$B:$B,">="&EOMONTH($D$12,-1)+1, 'Lead Tracker'!$B:$B,"<"&EOMONTH($D$12,0)+1 ) -> 0 | J15: =COUNTIFS('Lead Tracker'!$L:$L,D15,'Lead Tracker'!$J:$J,$J$3, 'Lead Tracker'!$B:$B,">="&EOMONTH($D$12,-1)+1, 'Lead Tracker'!$B:$B,"<"&EOMONTH($D$12,0)+1 ) -> 0 | K15: =COUNTIFS('Lead Tracker'!$L:$L,D15,'Lead Tracker'!$J:$J,$K$3, 'Lead Tracker'!$B:$B,">="&EOMONTH($D$12,-1)+1, 'Lead Tracker'!$B:$B,"<"&EOMONTH($D$12,0)+1 ) -> 0 | L15: =COUNTIFS('Lead Tracker'!$L:$L,D15,'Lead Tracker'!$J:$J,$L$3, 'Lead Tracker'!$B:$B,">="&EOMONTH($D$12,-1)+1, 'Lead Tracker'!$B:$B,"<"&EOMONTH($D$12,0)+1 ) -> 5 | M15: =COUNTIFS('Lead Tracker'!$L:$L,D15,'Lead Tracker'!$J:$J,$M$3, 'Lead Tracker'!$B:$B,">="&EOMONTH($D$12,-1)+1, 'Lead Tracker'!$B:$B,"<"&EOMONTH($D$12,0)+1 ) -> 0 | N15: =COUNTIFS('Lead Tracker'!$L:$L,D15,'Lead Tracker'!$J:$J,$N$3, 'Lead Tracker'!$B:$B,">="&EOMONTH($D$12,-1)+1, 'Lead Tracker'!$B:$B,"<"&EOMONTH($D$12,0)+1 ) -> 0 | O15: =COUNTIFS('Lead Tracker'!$L:$L,D15,'Lead Tracker'!$J:$J,$O$3, 'Lead Tracker'!$B:$B,">="&EOMONTH($D$12,-1)+1, 'Lead Tracker'!$B:$B,"<"&EOMONTH($D$12,0)+1 ) -> 0 | P15: =COUNTIFS('Lead Tracker'!$L:$L,D15,'Lead Tracker'!$J:$J,$P$3, 'Lead Tracker'!$B:$B,">="&EOMONTH($D$12,-1)+1, 'Lead Tracker'!$B:$B,"<"&EOMONTH($D$12,0)+1) -> 0
D16: EXISTING CUS. | E16: =COUNTIFS( 'Lead Tracker'!L:L,D16, 'Lead Tracker'!B:B,">="&EOMONTH($D$12,-1)+1, 'Lead Tracker'!B:B,"<"&EOMONTH($D$12,0)+1 ) -> 9 | F16: =COUNTIFS( 'Lead Tracker'!$L:$L,D16, 'Lead Tracker'!$J:$J,$F$3, 'Lead Tracker'!$B:$B,">="&EOMONTH($D$12,-1)+1, 'Lead Tracker'!$B:$B,"<"&EOMONTH($D$12,0)+1 ) -> 0 | G16: =COUNTIFS( 'Lead Tracker'!$L:$L,D16, 'Lead Tracker'!$J:$J,$G$3, 'Lead Tracker'!$B:$B,">="&EOMONTH($D$12,-1)+1, 'Lead Tracker'!$B:$B,"<"&EOMONTH($D$12,0)+1 ) -> 1 | H16: =COUNTIFS( 'Lead Tracker'!$L:$L,D16, 'Lead Tracker'!$J:$J,$H$3, 'Lead Tracker'!$B:$B,">="&EOMONTH($D$12,-1)+1, 'Lead Tracker'!$B:$B,"<"&EOMONTH($D$12,0)+1 ) -> 0 | I16: =COUNTIFS('Lead Tracker'!$L:$L,D16,'Lead Tracker'!$J:$J,$I$3,'Lead Tracker'!$B:$B,">="&EOMONTH($D$12,-1)+1, 'Lead Tracker'!$B:$B,"<"&EOMONTH($D$12,0)+1 ) -> 0 | J16: =COUNTIFS('Lead Tracker'!$L:$L,D16,'Lead Tracker'!$J:$J,$J$3, 'Lead Tracker'!$B:$B,">="&EOMONTH($D$12,-1)+1, 'Lead Tracker'!$B:$B,"<"&EOMONTH($D$12,0)+1 ) -> 0 | K16: =COUNTIFS('Lead Tracker'!$L:$L,D16,'Lead Tracker'!$J:$J,$K$3, 'Lead Tracker'!$B:$B,">="&EOMONTH($D$12,-1)+1, 'Lead Tracker'!$B:$B,"<"&EOMONTH($D$12,0)+1 ) -> 0 | L16: =COUNTIFS('Lead Tracker'!$L:$L,D16,'Lead Tracker'!$J:$J,$L$3, 'Lead Tracker'!$B:$B,">="&EOMONTH($D$12,-1)+1, 'Lead Tracker'!$B:$B,"<"&EOMONTH($D$12,0)+1 ) -> 8 | M16: =COUNTIFS('Lead Tracker'!$L:$L,D16,'Lead Tracker'!$J:$J,$M$3, 'Lead Tracker'!$B:$B,">="&EOMONTH($D$12,-1)+1, 'Lead Tracker'!$B:$B,"<"&EOMONTH($D$12,0)+1 ) -> 0 | N16: =COUNTIFS('Lead Tracker'!$L:$L,D16,'Lead Tracker'!$J:$J,$N$3, 'Lead Tracker'!$B:$B,">="&EOMONTH($D$12,-1)+1, 'Lead Tracker'!$B:$B,"<"&EOMONTH($D$12,0)+1 ) -> 0 | O16: =COUNTIFS('Lead Tracker'!$L:$L,D16,'Lead Tracker'!$J:$J,$O$3, 'Lead Tracker'!$B:$B,">="&EOMONTH($D$12,-1)+1, 'Lead Tracker'!$B:$B,"<"&EOMONTH($D$12,0)+1 ) -> 0 | P16: =COUNTIFS('Lead Tracker'!$L:$L,D16,'Lead Tracker'!$J:$J,$P$3, 'Lead Tracker'!$B:$B,">="&EOMONTH($D$12,-1)+1, 'Lead Tracker'!$B:$B,"<"&EOMONTH($D$12,0)+1) -> 0
D17: MAIL | E17: =COUNTIFS( 'Lead Tracker'!L:L,D17, 'Lead Tracker'!B:B,">="&EOMONTH($D$12,-1)+1, 'Lead Tracker'!B:B,"<"&EOMONTH($D$12,0)+1 ) -> 22 | F17: =COUNTIFS( 'Lead Tracker'!$L:$L,D17, 'Lead Tracker'!$J:$J,$F$3, 'Lead Tracker'!$B:$B,">="&EOMONTH($D$12,-1)+1, 'Lead Tracker'!$B:$B,"<"&EOMONTH($D$12,0)+1 ) -> 2 | G17: =COUNTIFS( 'Lead Tracker'!$L:$L,D17, 'Lead Tracker'!$J:$J,$G$3, 'Lead Tracker'!$B:$B,">="&EOMONTH($D$12,-1)+1, 'Lead Tracker'!$B:$B,"<"&EOMONTH($D$12,0)+1 ) -> 1 | H17: =COUNTIFS( 'Lead Tracker'!$L:$L,D17, 'Lead Tracker'!$J:$J,$H$3, 'Lead Tracker'!$B:$B,">="&EOMONTH($D$12,-1)+1, 'Lead Tracker'!$B:$B,"<"&EOMONTH($D$12,0)+1 ) -> 0 | I17: =COUNTIFS('Lead Tracker'!$L:$L,D17,'Lead Tracker'!$J:$J,$I$3,'Lead Tracker'!$B:$B,">="&EOMONTH($D$12,-1)+1, 'Lead Tracker'!$B:$B,"<"&EOMONTH($D$12,0)+1 ) -> 1 | J17: =COUNTIFS('Lead Tracker'!$L:$L,D17,'Lead Tracker'!$J:$J,$J$3, 'Lead Tracker'!$B:$B,">="&EOMONTH($D$12,-1)+1, 'Lead Tracker'!$B:$B,"<"&EOMONTH($D$12,0)+1 ) -> 0 | K17: =COUNTIFS('Lead Tracker'!$L:$L,D17,'Lead Tracker'!$J:$J,$K$3, 'Lead Tracker'!$B:$B,">="&EOMONTH($D$12,-1)+1, 'Lead Tracker'!$B:$B,"<"&EOMONTH($D$12,0)+1 ) -> 0 | L17: =COUNTIFS('Lead Tracker'!$L:$L,D17,'Lead Tracker'!$J:$J,$L$3, 'Lead Tracker'!$B:$B,">="&EOMONTH($D$12,-1)+1, 'Lead Tracker'!$B:$B,"<"&EOMONTH($D$12,0)+1 ) -> 16 | M17: =COUNTIFS('Lead Tracker'!$L:$L,D17,'Lead Tracker'!$J:$J,$M$3, 'Lead Tracker'!$B:$B,">="&EOMONTH($D$12,-1)+1, 'Lead Tracker'!$B:$B,"<"&EOMONTH($D$12,0)+1 ) -> 0 | N17: =COUNTIFS('Lead Tracker'!$L:$L,D17,'Lead Tracker'!$J:$J,$N$3, 'Lead Tracker'!$B:$B,">="&EOMONTH($D$12,-1)+1, 'Lead Tracker'!$B:$B,"<"&EOMONTH($D$12,0)+1 ) -> 0 | O17: =COUNTIFS('Lead Tracker'!$L:$L,D17,'Lead Tracker'!$J:$J,$O$3, 'Lead Tracker'!$B:$B,">="&EOMONTH($D$12,-1)+1, 'Lead Tracker'!$B:$B,"<"&EOMONTH($D$12,0)+1 ) -> 0 | P17: =COUNTIFS('Lead Tracker'!$L:$L,D17,'Lead Tracker'!$J:$J,$P$3, 'Lead Tracker'!$B:$B,">="&EOMONTH($D$12,-1)+1, 'Lead Tracker'!$B:$B,"<"&EOMONTH($D$12,0)+1) -> 2
D18: INDIAMART | E18: =COUNTIFS( 'Lead Tracker'!L:L,D18, 'Lead Tracker'!B:B,">="&EOMONTH($D$12,-1)+1, 'Lead Tracker'!B:B,"<"&EOMONTH($D$12,0)+1 ) -> 58 | F18: =COUNTIFS( 'Lead Tracker'!$L:$L,D18, 'Lead Tracker'!$J:$J,$F$3, 'Lead Tracker'!$B:$B,">="&EOMONTH($D$12,-1)+1, 'Lead Tracker'!$B:$B,"<"&EOMONTH($D$12,0)+1 ) -> 9 | G18: =COUNTIFS( 'Lead Tracker'!$L:$L,D18, 'Lead Tracker'!$J:$J,$G$3, 'Lead Tracker'!$B:$B,">="&EOMONTH($D$12,-1)+1, 'Lead Tracker'!$B:$B,"<"&EOMONTH($D$12,0)+1 ) -> 0 | H18: =COUNTIFS( 'Lead Tracker'!$L:$L,D18, 'Lead Tracker'!$J:$J,$H$3, 'Lead Tracker'!$B:$B,">="&EOMONTH($D$12,-1)+1, 'Lead Tracker'!$B:$B,"<"&EOMONTH($D$12,0)+1 ) -> 3 | I18: =COUNTIFS('Lead Tracker'!$L:$L,D18,'Lead Tracker'!$J:$J,$I$3,'Lead Tracker'!$B:$B,">="&EOMONTH($D$12,-1)+1, 'Lead Tracker'!$B:$B,"<"&EOMONTH($D$12,0)+1 ) -> 7 | J18: =COUNTIFS('Lead Tracker'!$L:$L,D18,'Lead Tracker'!$J:$J,$J$3, 'Lead Tracker'!$B:$B,">="&EOMONTH($D$12,-1)+1, 'Lead Tracker'!$B:$B,"<"&EOMONTH($D$12,0)+1 ) -> 10 | K18: =COUNTIFS('Lead Tracker'!$L:$L,D18,'Lead Tracker'!$J:$J,$K$3, 'Lead Tracker'!$B:$B,">="&EOMONTH($D$12,-1)+1, 'Lead Tracker'!$B:$B,"<"&EOMONTH($D$12,0)+1 ) -> 1 | L18: =COUNTIFS('Lead Tracker'!$L:$L,D18,'Lead Tracker'!$J:$J,$L$3, 'Lead Tracker'!$B:$B,">="&EOMONTH($D$12,-1)+1, 'Lead Tracker'!$B:$B,"<"&EOMONTH($D$12,0)+1 ) -> 10 | M18: =COUNTIFS('Lead Tracker'!$L:$L,D18,'Lead Tracker'!$J:$J,$M$3, 'Lead Tracker'!$B:$B,">="&EOMONTH($D$12,-1)+1, 'Lead Tracker'!$B:$B,"<"&EOMONTH($D$12,0)+1 ) -> 9 | N18: =COUNTIFS('Lead Tracker'!$L:$L,D18,'Lead Tracker'!$J:$J,$N$3, 'Lead Tracker'!$B:$B,">="&EOMONTH($D$12,-1)+1, 'Lead Tracker'!$B:$B,"<"&EOMONTH($D$12,0)+1 ) -> 9 | O18: =COUNTIFS('Lead Tracker'!$L:$L,D18,'Lead Tracker'!$J:$J,$O$3, 'Lead Tracker'!$B:$B,">="&EOMONTH($D$12,-1)+1, 'Lead Tracker'!$B:$B,"<"&EOMONTH($D$12,0)+1 ) -> 0 | P18: =COUNTIFS('Lead Tracker'!$L:$L,D18,'Lead Tracker'!$J:$J,$P$3, 'Lead Tracker'!$B:$B,">="&EOMONTH($D$12,-1)+1, 'Lead Tracker'!$B:$B,"<"&EOMONTH($D$12,0)+1) -> 0
D19: OUT SOURCE | E19: =COUNTIFS( 'Lead Tracker'!L:L,D19, 'Lead Tracker'!B:B,">="&EOMONTH($D$12,-1)+1, 'Lead Tracker'!B:B,"<"&EOMONTH($D$12,0)+1 ) -> 2 | F19: =COUNTIFS( 'Lead Tracker'!$L:$L,D19, 'Lead Tracker'!$J:$J,$F$3, 'Lead Tracker'!$B:$B,">="&EOMONTH($D$12,-1)+1, 'Lead Tracker'!$B:$B,"<"&EOMONTH($D$12,0)+1 ) -> 0 | G19: =COUNTIFS( 'Lead Tracker'!$L:$L,D19, 'Lead Tracker'!$J:$J,$G$3, 'Lead Tracker'!$B:$B,">="&EOMONTH($D$12,-1)+1, 'Lead Tracker'!$B:$B,"<"&EOMONTH($D$12,0)+1 ) -> 0 | H19: =COUNTIFS( 'Lead Tracker'!$L:$L,D19, 'Lead Tracker'!$J:$J,$H$3, 'Lead Tracker'!$B:$B,">="&EOMONTH($D$12,-1)+1, 'Lead Tracker'!$B:$B,"<"&EOMONTH($D$12,0)+1 ) -> 0 | I19: =COUNTIFS('Lead Tracker'!$L:$L,D19,'Lead Tracker'!$J:$J,$I$3,'Lead Tracker'!$B:$B,">="&EOMONTH($D$12,-1)+1, 'Lead Tracker'!$B:$B,"<"&EOMONTH($D$12,0)+1 ) -> 1 | J19: =COUNTIFS('Lead Tracker'!$L:$L,D19,'Lead Tracker'!$J:$J,$J$3, 'Lead Tracker'!$B:$B,">="&EOMONTH($D$12,-1)+1, 'Lead Tracker'!$B:$B,"<"&EOMONTH($D$12,0)+1 ) -> 0 | K19: =COUNTIFS('Lead Tracker'!$L:$L,D19,'Lead Tracker'!$J:$J,$K$3, 'Lead Tracker'!$B:$B,">="&EOMONTH($D$12,-1)+1, 'Lead Tracker'!$B:$B,"<"&EOMONTH($D$12,0)+1 ) -> 0 | L19: =COUNTIFS('Lead Tracker'!$L:$L,D19,'Lead Tracker'!$J:$J,$L$3, 'Lead Tracker'!$B:$B,">="&EOMONTH($D$12,-1)+1, 'Lead Tracker'!$B:$B,"<"&EOMONTH($D$12,0)+1 ) -> 1 | M19: =COUNTIFS('Lead Tracker'!$L:$L,D19,'Lead Tracker'!$J:$J,$M$3, 'Lead Tracker'!$B:$B,">="&EOMONTH($D$12,-1)+1, 'Lead Tracker'!$B:$B,"<"&EOMONTH($D$12,0)+1 ) -> 0 | N19: =COUNTIFS('Lead Tracker'!$L:$L,D19,'Lead Tracker'!$J:$J,$N$3, 'Lead Tracker'!$B:$B,">="&EOMONTH($D$12,-1)+1, 'Lead Tracker'!$B:$B,"<"&EOMONTH($D$12,0)+1 ) -> 0 | O19: =COUNTIFS('Lead Tracker'!$L:$L,D19,'Lead Tracker'!$J:$J,$O$3, 'Lead Tracker'!$B:$B,">="&EOMONTH($D$12,-1)+1, 'Lead Tracker'!$B:$B,"<"&EOMONTH($D$12,0)+1 ) -> 0 | P19: =COUNTIFS('Lead Tracker'!$L:$L,D19,'Lead Tracker'!$J:$J,$P$3, 'Lead Tracker'!$B:$B,">="&EOMONTH($D$12,-1)+1, 'Lead Tracker'!$B:$B,"<"&EOMONTH($D$12,0)+1) -> 0
D20: TRADEINDIA | E20: =COUNTIFS( 'Lead Tracker'!L:L,D20, 'Lead Tracker'!B:B,">="&EOMONTH($D$12,-1)+1, 'Lead Tracker'!B:B,"<"&EOMONTH($D$12,0)+1 ) -> 29 | F20: =COUNTIFS( 'Lead Tracker'!$L:$L,D20, 'Lead Tracker'!$J:$J,$F$3, 'Lead Tracker'!$B:$B,">="&EOMONTH($D$12,-1)+1, 'Lead Tracker'!$B:$B,"<"&EOMONTH($D$12,0)+1 ) -> 6 | G20: =COUNTIFS( 'Lead Tracker'!$L:$L,D20, 'Lead Tracker'!$J:$J,$G$3, 'Lead Tracker'!$B:$B,">="&EOMONTH($D$12,-1)+1, 'Lead Tracker'!$B:$B,"<"&EOMONTH($D$12,0)+1 ) -> 0 | H20: =COUNTIFS( 'Lead Tracker'!$L:$L,D20, 'Lead Tracker'!$J:$J,$H$3, 'Lead Tracker'!$B:$B,">="&EOMONTH($D$12,-1)+1, 'Lead Tracker'!$B:$B,"<"&EOMONTH($D$12,0)+1 ) -> 2 | I20: =COUNTIFS('Lead Tracker'!$L:$L,D20,'Lead Tracker'!$J:$J,$I$3,'Lead Tracker'!$B:$B,">="&EOMONTH($D$12,-1)+1, 'Lead Tracker'!$B:$B,"<"&EOMONTH($D$12,0)+1 ) -> 1 | J20: =COUNTIFS('Lead Tracker'!$L:$L,D20,'Lead Tracker'!$J:$J,$J$3, 'Lead Tracker'!$B:$B,">="&EOMONTH($D$12,-1)+1, 'Lead Tracker'!$B:$B,"<"&EOMONTH($D$12,0)+1 ) -> 4 | K20: =COUNTIFS('Lead Tracker'!$L:$L,D20,'Lead Tracker'!$J:$J,$K$3, 'Lead Tracker'!$B:$B,">="&EOMONTH($D$12,-1)+1, 'Lead Tracker'!$B:$B,"<"&EOMONTH($D$12,0)+1 ) -> 0 | L20: =COUNTIFS('Lead Tracker'!$L:$L,D20,'Lead Tracker'!$J:$J,$L$3, 'Lead Tracker'!$B:$B,">="&EOMONTH($D$12,-1)+1, 'Lead Tracker'!$B:$B,"<"&EOMONTH($D$12,0)+1 ) -> 2 | M20: =COUNTIFS('Lead Tracker'!$L:$L,D20,'Lead Tracker'!$J:$J,$M$3, 'Lead Tracker'!$B:$B,">="&EOMONTH($D$12,-1)+1, 'Lead Tracker'!$B:$B,"<"&EOMONTH($D$12,0)+1 ) -> 5 | N20: =COUNTIFS('Lead Tracker'!$L:$L,D20,'Lead Tracker'!$J:$J,$N$3, 'Lead Tracker'!$B:$B,">="&EOMONTH($D$12,-1)+1, 'Lead Tracker'!$B:$B,"<"&EOMONTH($D$12,0)+1 ) -> 7 | O20: =COUNTIFS('Lead Tracker'!$L:$L,D20,'Lead Tracker'!$J:$J,$O$3, 'Lead Tracker'!$B:$B,">="&EOMONTH($D$12,-1)+1, 'Lead Tracker'!$B:$B,"<"&EOMONTH($D$12,0)+1 ) -> 2 | P20: =COUNTIFS('Lead Tracker'!$L:$L,D20,'Lead Tracker'!$J:$J,$P$3, 'Lead Tracker'!$B:$B,">="&EOMONTH($D$12,-1)+1, 'Lead Tracker'!$B:$B,"<"&EOMONTH($D$12,0)+1) -> 0
D22: LEAD OWNER
D23: LEAD SOURCES | F23: NEW | G23: WIN | H23: LOST | I23: CONTACTED | J23: NOT INTERESTED | K23: SITE VISIT REQ. | L23: QUOTATION REQ. | M23: NOT RECEIVED | N23: FAKE | O23: FULFILLED | P23: QUOTATION SHARED | R23: =D22 -> LEAD OWNER
D24: MALLESH | E24: =COUNTIFS( 'Lead Tracker'!M:M,D24, 'Lead Tracker'!B:B,">="&EOMONTH($D$12,-1)+1, 'Lead Tracker'!B:B,"<"&EOMONTH($D$12,0)+1 ) -> 6 | F24: =COUNTIFS( 'Lead Tracker'!$M:$M,D24, 'Lead Tracker'!$J:$J,$F$3, 'Lead Tracker'!$B:$B,">="&EOMONTH($D$12,-1)+1, 'Lead Tracker'!$B:$B,"<"&EOMONTH($D$12,0)+1 ) -> 0 | G24: =COUNTIFS( 'Lead Tracker'!$M:$M,D24, 'Lead Tracker'!$J:$J,$G$3, 'Lead Tracker'!$B:$B,">="&EOMONTH($D$12,-1)+1, 'Lead Tracker'!$B:$B,"<"&EOMONTH($D$12,0)+1 ) -> 0 | H24: =COUNTIFS( 'Lead Tracker'!$M:$M,D24, 'Lead Tracker'!$J:$J,$H$3, 'Lead Tracker'!$B:$B,">="&EOMONTH($D$12,-1)+1, 'Lead Tracker'!$B:$B,"<"&EOMONTH($D$12,0)+1 ) -> 0 | I24: =COUNTIFS('Lead Tracker'!$M:$M,D24,'Lead Tracker'!$J:$J,$I$3,'Lead Tracker'!$B:$B,">="&EOMONTH($D$12,-1)+1, 'Lead Tracker'!$B:$B,"<"&EOMONTH($D$12,0)+1 ) -> 0 | J24: =COUNTIFS('Lead Tracker'!$M:$M,D24,'Lead Tracker'!$J:$J,$J$3, 'Lead Tracker'!$B:$B,">="&EOMONTH($D$12,-1)+1, 'Lead Tracker'!$B:$B,"<"&EOMONTH($D$12,0)+1 ) -> 0 | K24: =COUNTIFS('Lead Tracker'!$M:$M,D24,'Lead Tracker'!$J:$J,$K$3, 'Lead Tracker'!$B:$B,">="&EOMONTH($D$12,-1)+1, 'Lead Tracker'!$B:$B,"<"&EOMONTH($D$12,0)+1 ) -> 0 | L24: =COUNTIFS('Lead Tracker'!$M:$M,D24,'Lead Tracker'!$J:$J,$L$3, 'Lead Tracker'!$B:$B,">="&EOMONTH($D$12,-1)+1, 'Lead Tracker'!$B:$B,"<"&EOMONTH($D$12,0)+1 ) -> 6 | M24: =COUNTIFS('Lead Tracker'!$M:$M,D24,'Lead Tracker'!$J:$J,$M$3, 'Lead Tracker'!$B:$B,">="&EOMONTH($D$12,-1)+1, 'Lead Tracker'!$B:$B,"<"&EOMONTH($D$12,0)+1 ) -> 0 | N24: =COUNTIFS('Lead Tracker'!$M:$M,D24,'Lead Tracker'!$J:$J,$N$3, 'Lead Tracker'!$B:$B,">="&EOMONTH($D$12,-1)+1, 'Lead Tracker'!$B:$B,"<"&EOMONTH($D$12,0)+1 ) -> 0 | O24: =COUNTIFS('Lead Tracker'!$M:$M,D24,'Lead Tracker'!$J:$J,$O$3, 'Lead Tracker'!$B:$B,">="&EOMONTH($D$12,-1)+1, 'Lead Tracker'!$B:$B,"<"&EOMONTH($D$12,0)+1 ) -> 0 | P24: =COUNTIFS('Lead Tracker'!$M:$M,D24,'Lead Tracker'!$J:$J,$P$3, 'Lead Tracker'!$B:$B,">="&EOMONTH($D$12,-1)+1, 'Lead Tracker'!$B:$B,"<"&EOMONTH($D$12,0)+1) -> 0
D25: RAVI | E25: =COUNTIFS( 'Lead Tracker'!M:M,D25, 'Lead Tracker'!B:B,">="&EOMONTH($D$12,-1)+1, 'Lead Tracker'!B:B,"<"&EOMONTH($D$12,0)+1 ) -> 18 | F25: =COUNTIFS( 'Lead Tracker'!$M:$M,D25, 'Lead Tracker'!$J:$J,$F$3, 'Lead Tracker'!$B:$B,">="&EOMONTH($D$12,-1)+1, 'Lead Tracker'!$B:$B,"<"&EOMONTH($D$12,0)+1 ) -> 3 | G25: =COUNTIFS( 'Lead Tracker'!$M:$M,D25, 'Lead Tracker'!$J:$J,$G$3, 'Lead Tracker'!$B:$B,">="&EOMONTH($D$12,-1)+1, 'Lead Tracker'!$B:$B,"<"&EOMONTH($D$12,0)+1 ) -> 0 | H25: =COUNTIFS( 'Lead Tracker'!$M:$M,D25, 'Lead Tracker'!$J:$J,$H$3, 'Lead Tracker'!$B:$B,">="&EOMONTH($D$12,-1)+1, 'Lead Tracker'!$B:$B,"<"&EOMONTH($D$12,0)+1 ) -> 0 | I25: =COUNTIFS('Lead Tracker'!$M:$M,D25,'Lead Tracker'!$J:$J,$I$3,'Lead Tracker'!$B:$B,">="&EOMONTH($D$12,-1)+1, 'Lead Tracker'!$B:$B,"<"&EOMONTH($D$12,0)+1 ) -> 0 | J25: =COUNTIFS('Lead Tracker'!$M:$M,D25,'Lead Tracker'!$J:$J,$J$3, 'Lead Tracker'!$B:$B,">="&EOMONTH($D$12,-1)+1, 'Lead Tracker'!$B:$B,"<"&EOMONTH($D$12,0)+1 ) -> 0 | K25: =COUNTIFS('Lead Tracker'!$M:$M,D25,'Lead Tracker'!$J:$J,$K$3, 'Lead Tracker'!$B:$B,">="&EOMONTH($D$12,-1)+1, 'Lead Tracker'!$B:$B,"<"&EOMONTH($D$12,0)+1 ) -> 0 | L25: =COUNTIFS('Lead Tracker'!$M:$M,D25,'Lead Tracker'!$J:$J,$L$3, 'Lead Tracker'!$B:$B,">="&EOMONTH($D$12,-1)+1, 'Lead Tracker'!$B:$B,"<"&EOMONTH($D$12,0)+1 ) -> 15 | M25: =COUNTIFS('Lead Tracker'!$M:$M,D25,'Lead Tracker'!$J:$J,$M$3, 'Lead Tracker'!$B:$B,">="&EOMONTH($D$12,-1)+1, 'Lead Tracker'!$B:$B,"<"&EOMONTH($D$12,0)+1 ) -> 0 | N25: =COUNTIFS('Lead Tracker'!$M:$M,D25,'Lead Tracker'!$J:$J,$N$3, 'Lead Tracker'!$B:$B,">="&EOMONTH($D$12,-1)+1, 'Lead Tracker'!$B:$B,"<"&EOMONTH($D$12,0)+1 ) -> 0 | O25: =COUNTIFS('Lead Tracker'!$M:$M,D25,'Lead Tracker'!$J:$J,$O$3, 'Lead Tracker'!$B:$B,">="&EOMONTH($D$12,-1)+1, 'Lead Tracker'!$B:$B,"<"&EOMONTH($D$12,0)+1 ) -> 0 | P25: =COUNTIFS('Lead Tracker'!$M:$M,D25,'Lead Tracker'!$J:$J,$P$3, 'Lead Tracker'!$B:$B,">="&EOMONTH($D$12,-1)+1, 'Lead Tracker'!$B:$B,"<"&EOMONTH($D$12,0)+1) -> 0
D26: HARSH | E26: =COUNTIFS( 'Lead Tracker'!M:M,D26, 'Lead Tracker'!B:B,">="&EOMONTH($D$12,-1)+1, 'Lead Tracker'!B:B,"<"&EOMONTH($D$12,0)+1 ) -> 2 | F26: =COUNTIFS( 'Lead Tracker'!$M:$M,D26, 'Lead Tracker'!$J:$J,$F$3, 'Lead Tracker'!$B:$B,">="&EOMONTH($D$12,-1)+1, 'Lead Tracker'!$B:$B,"<"&EOMONTH($D$12,0)+1 ) -> 0 | G26: =COUNTIFS( 'Lead Tracker'!$M:$M,D26, 'Lead Tracker'!$J:$J,$G$3, 'Lead Tracker'!$B:$B,">="&EOMONTH($D$12,-1)+1, 'Lead Tracker'!$B:$B,"<"&EOMONTH($D$12,0)+1 ) -> 0 | H26: =COUNTIFS( 'Lead Tracker'!$M:$M,D26, 'Lead Tracker'!$J:$J,$H$3, 'Lead Tracker'!$B:$B,">="&EOMONTH($D$12,-1)+1, 'Lead Tracker'!$B:$B,"<"&EOMONTH($D$12,0)+1 ) -> 0 | I26: =COUNTIFS('Lead Tracker'!$M:$M,D26,'Lead Tracker'!$J:$J,$I$3,'Lead Tracker'!$B:$B,">="&EOMONTH($D$12,-1)+1, 'Lead Tracker'!$B:$B,"<"&EOMONTH($D$12,0)+1 ) -> 1 | J26: =COUNTIFS('Lead Tracker'!$M:$M,D26,'Lead Tracker'!$J:$J,$J$3, 'Lead Tracker'!$B:$B,">="&EOMONTH($D$12,-1)+1, 'Lead Tracker'!$B:$B,"<"&EOMONTH($D$12,0)+1 ) -> 0 | K26: =COUNTIFS('Lead Tracker'!$M:$M,D26,'Lead Tracker'!$J:$J,$K$3, 'Lead Tracker'!$B:$B,">="&EOMONTH($D$12,-1)+1, 'Lead Tracker'!$B:$B,"<"&EOMONTH($D$12,0)+1 ) -> 0 | L26: =COUNTIFS('Lead Tracker'!$M:$M,D26,'Lead Tracker'!$J:$J,$L$3, 'Lead Tracker'!$B:$B,">="&EOMONTH($D$12,-1)+1, 'Lead Tracker'!$B:$B,"<"&EOMONTH($D$12,0)+1 ) -> 1 | M26: =COUNTIFS('Lead Tracker'!$M:$M,D26,'Lead Tracker'!$J:$J,$M$3, 'Lead Tracker'!$B:$B,">="&EOMONTH($D$12,-1)+1, 'Lead Tracker'!$B:$B,"<"&EOMONTH($D$12,0)+1 ) -> 0 | N26: =COUNTIFS('Lead Tracker'!$M:$M,D26,'Lead Tracker'!$J:$J,$N$3, 'Lead Tracker'!$B:$B,">="&EOMONTH($D$12,-1)+1, 'Lead Tracker'!$B:$B,"<"&EOMONTH($D$12,0)+1 ) -> 0 | O26: =COUNTIFS('Lead Tracker'!$M:$M,D26,'Lead Tracker'!$J:$J,$O$3, 'Lead Tracker'!$B:$B,">="&EOMONTH($D$12,-1)+1, 'Lead Tracker'!$B:$B,"<"&EOMONTH($D$12,0)+1 ) -> 0 | P26: =COUNTIFS('Lead Tracker'!$M:$M,D26,'Lead Tracker'!$J:$J,$P$3, 'Lead Tracker'!$B:$B,">="&EOMONTH($D$12,-1)+1, 'Lead Tracker'!$B:$B,"<"&EOMONTH($D$12,0)+1) -> 0
D27: VIVEK | E27: =COUNTIFS( 'Lead Tracker'!M:M,D27, 'Lead Tracker'!B:B,">="&EOMONTH($D$12,-1)+1, 'Lead Tracker'!B:B,"<"&EOMONTH($D$12,0)+1 ) -> 61 | F27: =COUNTIFS( 'Lead Tracker'!$M:$M,D27, 'Lead Tracker'!$J:$J,$F$3, 'Lead Tracker'!$B:$B,">="&EOMONTH($D$12,-1)+1, 'Lead Tracker'!$B:$B,"<"&EOMONTH($D$12,0)+1 ) -> 12 | G27: =COUNTIFS( 'Lead Tracker'!$M:$M,D27, 'Lead Tracker'!$J:$J,$G$3, 'Lead Tracker'!$B:$B,">="&EOMONTH($D$12,-1)+1, 'Lead Tracker'!$B:$B,"<"&EOMONTH($D$12,0)+1 ) -> 1 | H27: =COUNTIFS( 'Lead Tracker'!$M:$M,D27, 'Lead Tracker'!$J:$J,$H$3, 'Lead Tracker'!$B:$B,">="&EOMONTH($D$12,-1)+1, 'Lead Tracker'!$B:$B,"<"&EOMONTH($D$12,0)+1 ) -> 3 | I27: =COUNTIFS('Lead Tracker'!$M:$M,D27,'Lead Tracker'!$J:$J,$I$3,'Lead Tracker'!$B:$B,">="&EOMONTH($D$12,-1)+1, 'Lead Tracker'!$B:$B,"<"&EOMONTH($D$12,0)+1 ) -> 4 | J27: =COUNTIFS('Lead Tracker'!$M:$M,D27,'Lead Tracker'!$J:$J,$J$3, 'Lead Tracker'!$B:$B,">="&EOMONTH($D$12,-1)+1, 'Lead Tracker'!$B:$B,"<"&EOMONTH($D$12,0)+1 ) -> 6 | K27: =COUNTIFS('Lead Tracker'!$M:$M,D27,'Lead Tracker'!$J:$J,$K$3, 'Lead Tracker'!$B:$B,">="&EOMONTH($D$12,-1)+1, 'Lead Tracker'!$B:$B,"<"&EOMONTH($D$12,0)+1 ) -> 0 | L27: =COUNTIFS('Lead Tracker'!$M:$M,D27,'Lead Tracker'!$J:$J,$L$3, 'Lead Tracker'!$B:$B,">="&EOMONTH($D$12,-1)+1, 'Lead Tracker'!$B:$B,"<"&EOMONTH($D$12,0)+1 ) -> 12 | M27: =COUNTIFS('Lead Tracker'!$M:$M,D27,'Lead Tracker'!$J:$J,$M$3, 'Lead Tracker'!$B:$B,">="&EOMONTH($D$12,-1)+1, 'Lead Tracker'!$B:$B,"<"&EOMONTH($D$12,0)+1 ) -> 8 | N27: =COUNTIFS('Lead Tracker'!$M:$M,D27,'Lead Tracker'!$J:$J,$N$3, 'Lead Tracker'!$B:$B,">="&EOMONTH($D$12,-1)+1, 'Lead Tracker'!$B:$B,"<"&EOMONTH($D$12,0)+1 ) -> 12 | O27: =COUNTIFS('Lead Tracker'!$M:$M,D27,'Lead Tracker'!$J:$J,$O$3, 'Lead Tracker'!$B:$B,">="&EOMONTH($D$12,-1)+1, 'Lead Tracker'!$B:$B,"<"&EOMONTH($D$12,0)+1 ) -> 1 | P27: =COUNTIFS('Lead Tracker'!$M:$M,D27,'Lead Tracker'!$J:$J,$P$3, 'Lead Tracker'!$B:$B,">="&EOMONTH($D$12,-1)+1, 'Lead Tracker'!$B:$B,"<"&EOMONTH($D$12,0)+1) -> 2
D28: SAKSHI | E28: =COUNTIFS( 'Lead Tracker'!M:M,D28, 'Lead Tracker'!B:B,">="&EOMONTH($D$12,-1)+1, 'Lead Tracker'!B:B,"<"&EOMONTH($D$12,0)+1 ) -> 36 | F28: =COUNTIFS( 'Lead Tracker'!$M:$M,D28, 'Lead Tracker'!$J:$J,$F$3, 'Lead Tracker'!$B:$B,">="&EOMONTH($D$12,-1)+1, 'Lead Tracker'!$B:$B,"<"&EOMONTH($D$12,0)+1 ) -> 2 | G28: =COUNTIFS( 'Lead Tracker'!$M:$M,D28, 'Lead Tracker'!$J:$J,$G$3, 'Lead Tracker'!$B:$B,">="&EOMONTH($D$12,-1)+1, 'Lead Tracker'!$B:$B,"<"&EOMONTH($D$12,0)+1 ) -> 1 | H28: =COUNTIFS( 'Lead Tracker'!$M:$M,D28, 'Lead Tracker'!$J:$J,$H$3, 'Lead Tracker'!$B:$B,">="&EOMONTH($D$12,-1)+1, 'Lead Tracker'!$B:$B,"<"&EOMONTH($D$12,0)+1 ) -> 2 | I28: =COUNTIFS('Lead Tracker'!$M:$M,D28,'Lead Tracker'!$J:$J,$I$3,'Lead Tracker'!$B:$B,">="&EOMONTH($D$12,-1)+1, 'Lead Tracker'!$B:$B,"<"&EOMONTH($D$12,0)+1 ) -> 4 | J28: =COUNTIFS('Lead Tracker'!$M:$M,D28,'Lead Tracker'!$J:$J,$J$3, 'Lead Tracker'!$B:$B,">="&EOMONTH($D$12,-1)+1, 'Lead Tracker'!$B:$B,"<"&EOMONTH($D$12,0)+1 ) -> 8 | K28: =COUNTIFS('Lead Tracker'!$M:$M,D28,'Lead Tracker'!$J:$J,$K$3, 'Lead Tracker'!$B:$B,">="&EOMONTH($D$12,-1)+1, 'Lead Tracker'!$B:$B,"<"&EOMONTH($D$12,0)+1 ) -> 1 | L28: =COUNTIFS('Lead Tracker'!$M:$M,D28,'Lead Tracker'!$J:$J,$L$3, 'Lead Tracker'!$B:$B,">="&EOMONTH($D$12,-1)+1, 'Lead Tracker'!$B:$B,"<"&EOMONTH($D$12,0)+1 ) -> 8 | M28: =COUNTIFS('Lead Tracker'!$M:$M,D28,'Lead Tracker'!$J:$J,$M$3, 'Lead Tracker'!$B:$B,">="&EOMONTH($D$12,-1)+1, 'Lead Tracker'!$B:$B,"<"&EOMONTH($D$12,0)+1 ) -> 5 | N28: =COUNTIFS('Lead Tracker'!$M:$M,D28,'Lead Tracker'!$J:$J,$N$3, 'Lead Tracker'!$B:$B,">="&EOMONTH($D$12,-1)+1, 'Lead Tracker'!$B:$B,"<"&EOMONTH($D$12,0)+1 ) -> 4 | O28: =COUNTIFS('Lead Tracker'!$M:$M,D28,'Lead Tracker'!$J:$J,$O$3, 'Lead Tracker'!$B:$B,">="&EOMONTH($D$12,-1)+1, 'Lead Tracker'!$B:$B,"<"&EOMONTH($D$12,0)+1 ) -> 1 | P28: =COUNTIFS('Lead Tracker'!$M:$M,D28,'Lead Tracker'!$J:$J,$P$3, 'Lead Tracker'!$B:$B,">="&EOMONTH($D$12,-1)+1, 'Lead Tracker'!$B:$B,"<"&EOMONTH($D$12,0)+1) -> 0
D30: PRODUCTS
D31: LEAD SOURCES | F31: NEW | G31: WIN | H31: LOST | I31: CONTACTED | J31: NOT INTERESTED | K31: SITE VISIT REQ. | L31: QUOTATION REQ. | M31: NOT RECEIVED | N31: FAKE | O31: FULFILLED | P31: QUOTATION SHARED | R31: =D30 -> PRODUCTS
D32: Modification | E32: =COUNTIFS( 'Lead Tracker'!F:F,D32, 'Lead Tracker'!B:B,">="&EOMONTH($D$12,-1)+1, 'Lead Tracker'!B:B,"<"&EOMONTH($D$12,0)+1 ) -> 0 | F32: =COUNTIFS( 'Lead Tracker'!$F:$F,$D$32, 'Lead Tracker'!$J:$J,$F$3, 'Lead Tracker'!$B:$B,">="&EOMONTH($D$12,-1)+1, 'Lead Tracker'!$B:$B,"<"&EOMONTH($D$12,0)+1 ) -> 0 | G32: =COUNTIFS( 'Lead Tracker'!$F:$F,$D32, 'Lead Tracker'!$J:$J,G3, 'Lead Tracker'!$B:$B,">="&EOMONTH($D$12,-1)+1, 'Lead Tracker'!$B:$B,"<"&EOMONTH($D$12,0)+1 ) -> 0 | H32: =COUNTIFS( 'Lead Tracker'!$F:$F,$D32, 'Lead Tracker'!$J:$J,$H$3, 'Lead Tracker'!$B:$B,">="&EOMONTH($D$12,-1)+1, 'Lead Tracker'!$B:$B,"<"&EOMONTH($D$12,0)+1 ) -> 0 | I32: =COUNTIFS( 'Lead Tracker'!$F:$F,$D32, 'Lead Tracker'!$J:$J,$I$3, 'Lead Tracker'!$B:$B,">="&EOMONTH($D$12,-1)+1, 'Lead Tracker'!$B:$B,"<"&EOMONTH($D$12,0)+1 ) -> 0 | J32: =COUNTIFS( 'Lead Tracker'!$F:$F,$D32, 'Lead Tracker'!$J:$J,$J$3, 'Lead Tracker'!$B:$B,">="&EOMONTH($D$12,-1)+1, 'Lead Tracker'!$B:$B,"<"&EOMONTH($D$12,0)+1 ) -> 0 | K32: =COUNTIFS( 'Lead Tracker'!$F:$F,$D32, 'Lead Tracker'!$J:$J,$K$3, 'Lead Tracker'!$B:$B,">="&EOMONTH($D$12,-1)+1, 'Lead Tracker'!$B:$B,"<"&EOMONTH($D$12,0)+1 ) -> 0 | L32: =COUNTIFS( 'Lead Tracker'!$F:$F,$D32, 'Lead Tracker'!$J:$J,$L$3, 'Lead Tracker'!$B:$B,">="&EOMONTH($D$12,-1)+1, 'Lead Tracker'!$B:$B,"<"&EOMONTH($D$12,0)+1 ) -> 0 | M32: =COUNTIFS( 'Lead Tracker'!$F:$F,$D32, 'Lead Tracker'!$J:$J,$M$3, 'Lead Tracker'!$B:$B,">="&EOMONTH($D$12,-1)+1, 'Lead Tracker'!$B:$B,"<"&EOMONTH($D$12,0)+1 ) -> 0 | N32: =COUNTIFS( 'Lead Tracker'!$F:$F,$D32, 'Lead Tracker'!$J:$J,$N$3, 'Lead Tracker'!$B:$B,">="&EOMONTH($D$12,-1)+1, 'Lead Tracker'!$B:$B,"<"&EOMONTH($D$12,0)+1 ) -> 0 | O32: =COUNTIFS( 'Lead Tracker'!$F:$F,$D32, 'Lead Tracker'!$J:$J,$O$3, 'Lead Tracker'!$B:$B,">="&EOMONTH($D$12,-1)+1, 'Lead Tracker'!$B:$B,"<"&EOMONTH($D$12,0)+1 ) -> 0 | P32: =COUNTIFS( 'Lead Tracker'!$F:$F,$D32, 'Lead Tracker'!$J:$J,$P$3, 'Lead Tracker'!$B:$B,">="&EOMONTH($D$12,-1)+1, 'Lead Tracker'!$B:$B,"<"&EOMONTH($D$12,0)+1 ) -> 0
D33: LCS | E33: =COUNTIFS( 'Lead Tracker'!F:F,D33, 'Lead Tracker'!B:B,">="&EOMONTH($D$12,-1)+1, 'Lead Tracker'!B:B,"<"&EOMONTH($D$12,0)+1 ) -> 3 | F33: =COUNTIFS( 'Lead Tracker'!$F:$F,D33, 'Lead Tracker'!$J:$J,$F$3, 'Lead Tracker'!$B:$B,">="&EOMONTH($D$12,-1)+1, 'Lead Tracker'!$B:$B,"<"&EOMONTH($D$12,0)+1 ) -> 0 | G33: =COUNTIFS( 'Lead Tracker'!$F:$F,$D33, 'Lead Tracker'!$J:$J,$G$3, 'Lead Tracker'!$B:$B,">="&EOMONTH($D$12,-1)+1, 'Lead Tracker'!$B:$B,"<"&EOMONTH($D$12,0)+1 ) -> 0 | H33: =COUNTIFS( 'Lead Tracker'!$F:$F,$D33, 'Lead Tracker'!$J:$J,$H$3, 'Lead Tracker'!$B:$B,">="&EOMONTH($D$12,-1)+1, 'Lead Tracker'!$B:$B,"<"&EOMONTH($D$12,0)+1 ) -> 0 | I33: =COUNTIFS( 'Lead Tracker'!$F:$F,$D33, 'Lead Tracker'!$J:$J,$I$3, 'Lead Tracker'!$B:$B,">="&EOMONTH($D$12,-1)+1, 'Lead Tracker'!$B:$B,"<"&EOMONTH($D$12,0)+1 ) -> 0 | J33: =COUNTIFS( 'Lead Tracker'!$F:$F,$D33, 'Lead Tracker'!$J:$J,$J$3, 'Lead Tracker'!$B:$B,">="&EOMONTH($D$12,-1)+1, 'Lead Tracker'!$B:$B,"<"&EOMONTH($D$12,0)+1 ) -> 0 | K33: =COUNTIFS( 'Lead Tracker'!$F:$F,$D33, 'Lead Tracker'!$J:$J,$K$3, 'Lead Tracker'!$B:$B,">="&EOMONTH($D$12,-1)+1, 'Lead Tracker'!$B:$B,"<"&EOMONTH($D$12,0)+1 ) -> 0 | L33: =COUNTIFS( 'Lead Tracker'!$F:$F,$D33, 'Lead Tracker'!$J:$J,$L$3, 'Lead Tracker'!$B:$B,">="&EOMONTH($D$12,-1)+1, 'Lead Tracker'!$B:$B,"<"&EOMONTH($D$12,0)+1 ) -> 3 | M33: =COUNTIFS( 'Lead Tracker'!$F:$F,$D33, 'Lead Tracker'!$J:$J,$M$3, 'Lead Tracker'!$B:$B,">="&EOMONTH($D$12,-1)+1, 'Lead Tracker'!$B:$B,"<"&EOMONTH($D$12,0)+1 ) -> 0 | N33: =COUNTIFS( 'Lead Tracker'!$F:$F,$D33, 'Lead Tracker'!$J:$J,$N$3, 'Lead Tracker'!$B:$B,">="&EOMONTH($D$12,-1)+1, 'Lead Tracker'!$B:$B,"<"&EOMONTH($D$12,0)+1 ) -> 0 | O33: =COUNTIFS( 'Lead Tracker'!$F:$F,$D33, 'Lead Tracker'!$J:$J,$O$3, 'Lead Tracker'!$B:$B,">="&EOMONTH($D$12,-1)+1, 'Lead Tracker'!$B:$B,"<"&EOMONTH($D$12,0)+1 ) -> 0 | P33: =COUNTIFS( 'Lead Tracker'!$F:$F,$D33, 'Lead Tracker'!$J:$J,$P$3, 'Lead Tracker'!$B:$B,">="&EOMONTH($D$12,-1)+1, 'Lead Tracker'!$B:$B,"<"&EOMONTH($D$12,0)+1 ) -> 0
D34: Monorail | E34: =COUNTIFS( 'Lead Tracker'!F:F,D34, 'Lead Tracker'!B:B,">="&EOMONTH($D$12,-1)+1, 'Lead Tracker'!B:B,"<"&EOMONTH($D$12,0)+1 ) -> 0 | F34: =COUNTIFS( 'Lead Tracker'!$F:$F,D34, 'Lead Tracker'!$J:$J,$F$3, 'Lead Tracker'!$B:$B,">="&EOMONTH($D$12,-1)+1, 'Lead Tracker'!$B:$B,"<"&EOMONTH($D$12,0)+1 ) -> 0 | G34: =COUNTIFS( 'Lead Tracker'!$F:$F,$D34, 'Lead Tracker'!$J:$J,$G$3, 'Lead Tracker'!$B:$B,">="&EOMONTH($D$12,-1)+1, 'Lead Tracker'!$B:$B,"<"&EOMONTH($D$12,0)+1 ) -> 0 | H34: =COUNTIFS( 'Lead Tracker'!$F:$F,$D34, 'Lead Tracker'!$J:$J,$H$3, 'Lead Tracker'!$B:$B,">="&EOMONTH($D$12,-1)+1, 'Lead Tracker'!$B:$B,"<"&EOMONTH($D$12,0)+1 ) -> 0 | I34: =COUNTIFS( 'Lead Tracker'!$F:$F,$D34, 'Lead Tracker'!$J:$J,$I$3, 'Lead Tracker'!$B:$B,">="&EOMONTH($D$12,-1)+1, 'Lead Tracker'!$B:$B,"<"&EOMONTH($D$12,0)+1 ) -> 0 | J34: =COUNTIFS( 'Lead Tracker'!$F:$F,$D34, 'Lead Tracker'!$J:$J,$J$3, 'Lead Tracker'!$B:$B,">="&EOMONTH($D$12,-1)+1, 'Lead Tracker'!$B:$B,"<"&EOMONTH($D$12,0)+1 ) -> 0 | K34: =COUNTIFS( 'Lead Tracker'!$F:$F,$D34, 'Lead Tracker'!$J:$J,$K$3, 'Lead Tracker'!$B:$B,">="&EOMONTH($D$12,-1)+1, 'Lead Tracker'!$B:$B,"<"&EOMONTH($D$12,0)+1 ) -> 0 | L34: =COUNTIFS( 'Lead Tracker'!$F:$F,$D34, 'Lead Tracker'!$J:$J,$L$3, 'Lead Tracker'!$B:$B,">="&EOMONTH($D$12,-1)+1, 'Lead Tracker'!$B:$B,"<"&EOMONTH($D$12,0)+1 ) -> 0 | M34: =COUNTIFS( 'Lead Tracker'!$F:$F,$D34, 'Lead Tracker'!$J:$J,$M$3, 'Lead Tracker'!$B:$B,">="&EOMONTH($D$12,-1)+1, 'Lead Tracker'!$B:$B,"<"&EOMONTH($D$12,0)+1 ) -> 0 | N34: =COUNTIFS( 'Lead Tracker'!$F:$F,$D34, 'Lead Tracker'!$J:$J,$N$3, 'Lead Tracker'!$B:$B,">="&EOMONTH($D$12,-1)+1, 'Lead Tracker'!$B:$B,"<"&EOMONTH($D$12,0)+1 ) -> 0 | O34: =COUNTIFS( 'Lead Tracker'!$F:$F,$D34, 'Lead Tracker'!$J:$J,$O$3, 'Lead Tracker'!$B:$B,">="&EOMONTH($D$12,-1)+1, 'Lead Tracker'!$B:$B,"<"&EOMONTH($D$12,0)+1 ) -> 0 | P34: =COUNTIFS( 'Lead Tracker'!$F:$F,$D34, 'Lead Tracker'!$J:$J,$P$3, 'Lead Tracker'!$B:$B,">="&EOMONTH($D$12,-1)+1, 'Lead Tracker'!$B:$B,"<"&EOMONTH($D$12,0)+1 ) -> 0
D35: EOT Crane | E35: =COUNTIFS( 'Lead Tracker'!F:F,D35, 'Lead Tracker'!B:B,">="&EOMONTH($D$12,-1)+1, 'Lead Tracker'!B:B,"<"&EOMONTH($D$12,0)+1 ) -> 30 | F35: =COUNTIFS( 'Lead Tracker'!$F:$F,D35, 'Lead Tracker'!$J:$J,$F$3, 'Lead Tracker'!$B:$B,">="&EOMONTH($D$12,-1)+1, 'Lead Tracker'!$B:$B,"<"&EOMONTH($D$12,0)+1 ) -> 2 | G35: =COUNTIFS( 'Lead Tracker'!$F:$F,$D35, 'Lead Tracker'!$J:$J,$G$3, 'Lead Tracker'!$B:$B,">="&EOMONTH($D$12,-1)+1, 'Lead Tracker'!$B:$B,"<"&EOMONTH($D$12,0)+1 ) -> 0 | H35: =COUNTIFS( 'Lead Tracker'!$F:$F,$D35, 'Lead Tracker'!$J:$J,$H$3, 'Lead Tracker'!$B:$B,">="&EOMONTH($D$12,-1)+1, 'Lead Tracker'!$B:$B,"<"&EOMONTH($D$12,0)+1 ) -> 1 | I35: =COUNTIFS( 'Lead Tracker'!$F:$F,$D35, 'Lead Tracker'!$J:$J,$I$3, 'Lead Tracker'!$B:$B,">="&EOMONTH($D$12,-1)+1, 'Lead Tracker'!$B:$B,"<"&EOMONTH($D$12,0)+1 ) -> 2 | J35: =COUNTIFS( 'Lead Tracker'!$F:$F,$D35, 'Lead Tracker'!$J:$J,$J$3, 'Lead Tracker'!$B:$B,">="&EOMONTH($D$12,-1)+1, 'Lead Tracker'!$B:$B,"<"&EOMONTH($D$12,0)+1 ) -> 5 | K35: =COUNTIFS( 'Lead Tracker'!$F:$F,$D35, 'Lead Tracker'!$J:$J,$K$3, 'Lead Tracker'!$B:$B,">="&EOMONTH($D$12,-1)+1, 'Lead Tracker'!$B:$B,"<"&EOMONTH($D$12,0)+1 ) -> 0 | L35: =COUNTIFS( 'Lead Tracker'!$F:$F,$D35, 'Lead Tracker'!$J:$J,$L$3, 'Lead Tracker'!$B:$B,">="&EOMONTH($D$12,-1)+1, 'Lead Tracker'!$B:$B,"<"&EOMONTH($D$12,0)+1 ) -> 9 | M35: =COUNTIFS( 'Lead Tracker'!$F:$F,$D35, 'Lead Tracker'!$J:$J,$M$3, 'Lead Tracker'!$B:$B,">="&EOMONTH($D$12,-1)+1, 'Lead Tracker'!$B:$B,"<"&EOMONTH($D$12,0)+1 ) -> 4 | N35: =COUNTIFS( 'Lead Tracker'!$F:$F,$D35, 'Lead Tracker'!$J:$J,$N$3, 'Lead Tracker'!$B:$B,">="&EOMONTH($D$12,-1)+1, 'Lead Tracker'!$B:$B,"<"&EOMONTH($D$12,0)+1 ) -> 6 | O35: =COUNTIFS( 'Lead Tracker'!$F:$F,$D35, 'Lead Tracker'!$J:$J,$O$3, 'Lead Tracker'!$B:$B,">="&EOMONTH($D$12,-1)+1, 'Lead Tracker'!$B:$B,"<"&EOMONTH($D$12,0)+1 ) -> 1 | P35: =COUNTIFS( 'Lead Tracker'!$F:$F,$D35, 'Lead Tracker'!$J:$J,$P$3, 'Lead Tracker'!$B:$B,">="&EOMONTH($D$12,-1)+1, 'Lead Tracker'!$B:$B,"<"&EOMONTH($D$12,0)+1 ) -> 0
